Workbook

Sheet Burton EE Ratios
A1: 3. Read the Burton case, then use the case attachment data (next 7 worksheets in this workbook) to:
A2: a. Compute the solvency, profitability, and asset management ratios listed below for Burton and EE for 2014-16. (Burton has been completed for you)
A3: b. Compute the Dupont Identity ROE components for Burton, EE, and Sensor Industry* (Burton has been completed for you)
A4: c. Compute Common Size Income Statements, 2015 and 2016 FCFF, and FCFE for Burton and EE (Burton has been completed for you)
C20: Burton | F20: EE
C21: 2014 | D21: 2015 | E21: 2016 | F21: 2014 | G21: 2015 | H21: 2016
A22: Growth Rates
A23: Sales (% Change) | C23: N/A | D23: 0.23 | E23: 0.193 | F23: N/A | G23: 0.211 | H23: 0.142
A24: EBITDA (% Change) | C24: N/A | D24: 0.089736842 | E24: 0.24024752 | F24: N/A | G24: 0.42977054 | H24: 0.062589404
A25: Net Income (% Change) | C25: N/A | D25: 0.066603257 | E25: 0.324669 | F25: N/A | G25: 0.47980975 | H25: 0.072515128
A26: Total Assets (% Change) | C26: N/A | D26: 0.15912124 | E26: 0.13957306 | F26: N/A | G26: 0.19608664 | H26: 0.18632011
A27: Internal Growth Rate | B27: ROA*Plow/(1-ROA*Plow) | C27: 0.033084233 | D27: 0.030363357 | E27: 0.035470077 | F27: 0.1534756 | G27: 0.19705545 | H27: 0.17484645
A28: Sustainable Growth Rate | B28: ROE*Plow/(1-ROE*Plow) | C28: 0.3517191 | D28: 0.27753158 | E28: 0.28777174 | F28: 0.28643584 | G28: 0.32949218 | H28: 0.26580476
A29: Short-term Solvency
A30: Current Ratio | B30: CA/CL | C30: 0.79746216 | D30: 0.78283904 | E30: 0.79163366 | F30: 2.0495532 | G30: 2.3838862 | H30: 2.6165695
A31: Quick Ratio | B31: (CA-Inv)/CL | C31: 0.44251681 | D31: 0.42239963 | E31: 0.43631262 | F31: 1.5605256 | G31: 1.6593063 | H31: 1.7986224
A32: Cash Ratio | B32: Cash/CL | C32: 0.059337179 | D32: 0.043201295 | E32: 0.044374527 | F32: 0.66264438 | G32: 0.61337602 | H32: 0.61230039
A33: Long-term Solvency | C33: Burton | F33: EE
A34: Liability /Equity Ratio | B34: L/E | C34: 7.125013 | D34: 6.3719316 | E34: 5.523559 | F34: 0.67344269 | G34: 0.5055226 | H34: 0.41098408
A35: Debt / Equity Ratio | B35: D/E | C35: 5.4822227 | D35: 4.8828729 | E35: 4.1476007 | F35: 0.40094173 | G35: 0.3015751 | H35: 0.21726289 | I35: Includes loans
A36: Net Debt / Equity Ratio | B36: (D-cash)/E | C36: 5.1845112 | D36: 4.6734729 | E36: 3.9507326 | F36: -0.04531128 | G36: -0.0085003409 | H36: -0.034382821
A37: Equity Multiplier | B37: A/E | C37: 8.125015 | D37: 7.3719331 | E37: 6.5235602 | F37: 1.6734328 | G37: 1.5055152 | H37: 1.4109782
A38: Times Interest Earned | B38: EBIT/Int | C38: 2.5193978 | D38: 2.4160536 | E38: 2.6485293 | F38: 16.533951 | G38: 23.987291 | H38: 25.654218
A39: EBITDA / Interest | B39: EBITDA/Int | C39: 2.9188145 | D39: 2.7792872 | E39: 3.0293636 | F39: 24.126955 | G39: 34.49601 | H39: 36.655094
A40: Cash Coverage Ratio | B40: Cash / Int | C40: 1.1299806 | D40: 0.88721489 | E40: 0.94400917 | F40: 20.236584 | G40: 18.6943 | H40: 19.204283
A41: Asset Management | C41: Burton | F41: EE
A42: Inventory Turnover | B42: COGS/Inv | C42: 1.6060606 | D42: 1.6022305 | E42: 1.6564885 | F42: 5.4507956 | G42: 4.3793103 | H42: 4.3389831
A43: Days in Inventory | B43: 365/ Inv TO | C43: 227.26415 | D43: 227.80742 | E43: 220.34562 | F43: 66.962702 | G43: 83.346457 | H43: 84.121094
A44: Receivables Turnover | B44: Sales/AR | C44: 4.0816327 | D44: 4.1152263 | E44: 4.0160643 | F44: 6.0606061 | G44: 6.0240964 | H44: 5.988024
A45: Day's Sales in Receivables | B45: 365/Rec TO | C45: 89.425 | D45: 88.695 | E45: 90.885 | F45: 60.225 | G45: 60.59 | H45: 60.955
A46: Total Asset Turnover | B46: Sales/Assets | C46: 0.83023708 | D46: 0.88100501 | E46: 0.92230943 | F46: 2.0715823 | G46: 2.0974117 | H46: 2.0190538
A47: Profitability Measures | C47: Burton | F47: EE
A48: (Net) Profit Margin | B48: NI/Sales | C48: 0.038572981 | D48: 0.033448835 | E48: 0.037140516 | F48: 0.064228644 | G48: 0.078485692 | H48: 0.073710238
A49: EBITDA/Sales | B49: EBITDA/Sales | C49: 0.114 | D49: 0.101 | E49: 0.105 | F49: 0.15347442 | G49: 0.1812 | H49: 0.1686
A50: Return on Assets (ROA) | B50: NI/Assets | C50: 0.032024719 | D50: 0.029468591 | E50: 0.034255048 | F50: 0.13305492 | G50: 0.16461681 | H50: 0.14882494
A51: DuPont Identity Components of ROE | C51: Burton | F51: EE | I51: Sensors Industry Average (Weight each component by (company sales in each year) / (total sales for all 4 companies in each year); Excludes Burton and EE
A52: Total Asset Turnover | B52: Sales/Assets | C52: =C46 -> 0.83023708 | D52: =D46 -> 0.88100501 | E52: =E46 -> 0.92230943 | F52: =F46 -> 2.0715823 | G52: =G46 -> 2.0974117 | H52: =H46 -> 2.0190538 | I52: 0.59553859 | J52: 0.65999855 | K52: 0.64590608
A53: x Profit Margin | B53: NI/Sales | C53: =C48 -> 0.038572981 | D53: =D48 -> 0.033448835 | E53: =E48 -> 0.037140516 | F53: =F48 -> 0.064228644 | G53: =G48 -> 0.078485692 | H53: =H48 -> 0.073710238 | I53: 0.18493559 | J53: 0.15621204 | K53: 0.13497475
A54: x Equity Multiplier | B54: A/E | C54: =C37 -> 8.125015 | D54: =D37 -> 7.3719331 | E54: =E37 -> 6.5235602 | F54: =F37 -> 1.6734328 | G54: =G37 -> 1.5055152 | H54: =H37 -> 1.4109782 | I54: 2.1209136 | J54: 2.0968382 | K54: 1.9734581
A55: =Return on Equity (ROE) | B55: T/O*PM*Mult | C55: =C54*C53*C52 -> 0.26020132 | D55: =D54*D53*D52 -> 0.21724048 | E55: =E54*E53*E52 -> 0.22346486 | F55: =F52*F53*F54 -> 0.22265847 | G55: =G52*G53*G54 -> 0.24783311 | H55: =H52*H53*H54 -> 0.20998875 | I55: 0.23358953 | J55: 0.21618343 | K55: 0.17204807
...

Sheet Burton Stock Value
A9: Tax Rate | B9: 0.35 | D9: Enterprise Value | F9: 13040 | G9: Burton
A10: Perpetual FCFF Growth | B10: 0.03 | C10: T=6+ | D10: Stock Value per Share | F10: 4.62 | G10: Burton
A11: Discount Rate | B11: 0.085
A12: You may use this table/template if it helps
B13: 2016 | C13: 2017 | D13: 2018 | E13: 2019 | F13: 2020 | G13: 2021
C14: 1 | D14: 2 | E14: 3 | F14: 4 | G14: 5
A15: EBIT | B15: X | C15: 1231 | D15: 1428 | E15: 1525 | F15: 1599 | G15: 1694
A16: Tax | B16: X | C16: 431 | D16: 500 | E16: 534 | F16: 560 | G16: 593 | H16: <=Use tax rate
A17: EBIT - Tax | B17: X | C17: 800 | D17: 929 | E17: 992 | F17: 1039 | G17: 1101
A18: + Dep | B18: X | C18: 152 | D18: 177 | E18: 208 | F18: 239 | G18: 253
A19: - CAPEX | B19: X | C19: -346 | D19: -268 | E19: -144 | F19: -153 | G19: -162
A20: - Changes in NWC | B20: X | C20: -693 | D20: -596 | E20: -346 | F20: -280 | G20: -297
A21: FCFF | B21: X | C21: -86 | D21: 242 | E21: 709 | F21: 845 | G21: 896
A22: Terminal Value | B22: X | C22: X | D22: X | E22: X | F22: X | G22: 16771 | H22: <=growth perpetuity
A23: FCFF + Terminal Value | B23: X | C23: -86 | D23: 242 | E23: 709 | F23: 845 | G23: 17667
A25: A/R | B25: 2315 | C25: 2825 | D25: 3277 | E25: 3539 | F25: 3751 | G25: 3977
A26: Inventory | B26: 2436 | C26: 2998 | D26: 3478 | E26: 3756 | F26: 3981 | G26: 4220
A27: A/P | B27: -1153 | C27: -1384 | D27: -1605 | E27: -1733 | F27: -1837 | G27: -1948
A28: Accrued Expenses | B28: -567 | C28: -715 | D28: -829 | E28: -896 | F28: -949 | G28: -1006
A29: Non-cash NWC | B29: 3031 | C29: 3724 | D29: 4320 | E29: 4666 | F29: 4946 | G29: 5243
A31: Enterprise Value | B31: 13040
A32: Net Debt | B32: 6106
A33: Equity Value | B33: 6935
A34: Shares Outstand. | B34: 1500
A35: Stock Valuation per Share | B35: 4.62
A41: Burton 2016 EPS | B41: 0.23
A42: PE Ratio | B42: 21.65
A43: Burton Stock Value per share | B43: 4.98

Sheet Burton Thermowell
A5: FCFF IRR | B5: =IRR(B22:I22) -> 0.22343316 | F5: CAPEX | G5: T=0 | H5: 600000
A6: FCFF NPV | B6: =NPV(B9,C22:I22)+B22 -> 767922.74 | F6: Dep Life | H6: 7
A7: FCFF Payback | B7: 4 years | F7: Opex Labor | G7: T=1-7 | H7: 170000
A8: Tax | B8: 0.35 | F8: Other Opex | G8: T=1-7 | H8: 780000
A9: Discount Rate | B9: 0.085 | F9: NWC | G9: T=0-6 | H9: 650000
F10: Savings | G10: T=1-7 | H10: 1400000
A12: Year | B12: 0 | C12: 1 | D12: 2 | E12: 3 | F12: 4 | G12: 5 | H12: 6 | I12: 7
A13: Savings (Rev) | C13: =H10 -> 1400000 | D13: =C13 -> 1400000 | E13: =D13 -> 1400000 | F13: =E13 -> 1400000 | G13: =F13 -> 1400000 | H13: =G13 -> 1400000 | I13: =H13 -> 1400000
A14: Opex | C14: =H7+H8 -> 950000 | D14: =C14 -> 950000 | E14: =D14 -> 950000 | F14: =E14 -> 950000 | G14: =F14 -> 950000 | H14: =G14 -> 950000 | I14: =H14 -> 950000
A15: Dep | C15: =H5/H6 -> 85714.286 | D15: =C15 -> 85714.286 | E15: =D15 -> 85714.286 | F15: =E15 -> 85714.286 | G15: =F15 -> 85714.286 | H15: =G15 -> 85714.286 | I15: =H15 -> 85714.286
A16: EBIT | C16: =C13-C14-C15 -> 364285.71 | D16: =D13-D14-D15 -> 364285.71 | E16: =E13-E14-E15 -> 364285.71 | F16: =F13-F14-F15 -> 364285.71 | G16: =G13-G14-G15 -> 364285.71 | H16: =H13-H14-H15 -> 364285.71 | I16: =I13-I14-I15 -> 364285.71
A17: Tax | C17: =C16*$B$8 -> 127500 | D17: =D16*$B$8 -> 127500 | E17: =E16*$B$8 -> 127500 | F17: =F16*$B$8 -> 127500 | G17: =G16*$B$8 -> 127500 | H17: =H16*$B$8 -> 127500 | I17: =I16*$B$8 -> 127500
A18: EBIT - Tax | C18: =C16-C17 -> 236785.71 | D18: =D16-D17 -> 236785.71 | E18: =E16-E17 -> 236785.71 | F18: =F16-F17 -> 236785.71 | G18: =G16-G17 -> 236785.71 | H18: =H16-H17 -> 236785.71 | I18: =I16-I17 -> 236785.71
A19: Dep | C19: =+C15 -> 85714.286 | D19: =+D15 -> 85714.286 | E19: =+E15 -> 85714.286 | F19: =+F15 -> 85714.286 | G19: =+G15 -> 85714.286 | H19: =+H15 -> 85714.286 | I19: =+I15 -> 85714.286
A20: CAPEX | B20: =-H5 -> -600000
A21: Change in NWC | B21: -650000 | I21: =+H9 -> 650000
A22: Unlv FCF | B22: =+B18+B19+B20+B21 -> -1250000 | C22: =+C18+C19+C20+C21 -> 322500 | D22: =+D18+D19+D20+D21 -> 322500 | E22: =+E18+E19+E20+E21 -> 322500 | F22: =+F18+F19+F20+F21 -> 322500 | G22: =+G18+G19+G20+G21 -> 322500 | H22: =+H18+H19+H20+H21 -> 322500 | I22: =+I18+I19+I20+I21 -> 972500
B23: =B22 -> -1250000 | C23: =B23+C22 -> -927500 | D23: =C23+D22 -> -605000 | E23: =D23+E22 -> -282500 | F23: =E23+F22 -> 40000 | G23: =F23+G22 -> 362500
A28: Year | B28: 0 | C28: 1 | D28: 2 | E28: 3 | F28: 4 | G28: 5 | H28: 6 | I28: 7
A29: FCFE | B29: =B40 -> -625000 | C29: =C40 -> 224553.49 | D29: =D40 -> 223098.14 | E29: =E40 -> 221562.74 | F29: =F40 -> 219942.89 | G29: =G40 -> 218233.96 | H29: =H40 -> 216431.03 | I29: =I40 -> 864528.94
A31: Year | B31: 0 | C31: 1 | D31: 2 | E31: 3 | F31: 4 | G31: 5 | H31: 6 | I31: 7
A32: EBIT | C32: =C16 -> 364285.71 | D32: =D16 -> 364285.71 | E32: =E16 -> 364285.71 | F32: =F16 -> 364285.71 | G32: =G16 -> 364285.71 | H32: =H16 -> 364285.71 | I32: =I16 -> 364285.71
A33: Interest | C33: =C45 -> 34375 | D33: =D45 -> 30216.848 | E33: =E45 -> 25829.998 | F33: =F45 -> 21201.871 | G33: =G45 -> 16319.197 | H33: =H45 -> 11167.976 | I33: =I45 -> 5733.4378
A34: EBT | C34: =C32-C33 -> 329910.71 | D34: =D32-D33 -> 334068.87 | E34: =E32-E33 -> 338455.72 | F34: =F32-F33 -> 343083.84 | G34: =G32-G33 -> 347966.52 | H34: =H32-H33 -> 353117.74 | I34: =I32-I33 -> 358552.28
A35: Net Income | C35: =C34*(1-$B$8) -> 214441.96 | D35: =D34*(1-$B$8) -> 217144.76 | E35: =E34*(1-$B$8) -> 219996.22 | F35: =F34*(1-$B$8) -> 223004.5 | G35: =G34*(1-$B$8) -> 226178.24 | H35: =H34*(1-$B$8) -> 229526.53 | I35: =I34*(1-$B$8) -> 233058.98
A36: +Dep | C36: =+C19 -> 85714.286 | D36: =+D19 -> 85714.286 | E36: =+E19 -> 85714.286 | F36: =+F19 -> 85714.286 | G36: =+G19 -> 85714.286 | H36: =+H19 -> 85714.286 | I36: =+I19 -> 85714.286
A37: -CAPEX | B37: =B20 -> -600000
A38: -Change in NWC | B38: =B21 -> -650000 | I38: =I21 -> 650000
A39: +/- Loan Principal | B39: =C44 -> 625000 | C39: =-C46 -> -75602.761 | D39: =-D46 -> -79760.913 | E39: =-E46 -> -84147.763 | F39: =-F46 -> -88775.89 | G39: =-G46 -> -93658.564 | H39: =-H46 -> -98809.785 | I39: =-I46 -> -104244.32
A40: FCFE | B40: =SUM(B35:B39) -> -625000 | C40: =SUM(C35:C39) -> 224553.49 | D40: =SUM(D35:D39) -> 223098.14 | E40: =SUM(E35:E39) -> 221562.74 | F40: =SUM(F35:F39) -> 219942.89 | G40: =SUM(G35:G39) -> 218233.96 | H40: =SUM(H35:H39) -> 216431.03 | I40: =SUM(I35:I39) -> 864528.94
A42: Payment | B42: =PMT(0.055,7,0.5*B22) -> 109977.76
B43: 0 | C43: 1 | D43: 2 | E43: 3 | F43: 4 | G43: 5 | H43: 6 | I43: 7
A44: Loan Beg Balance | C44: =-B22*0.5 -> 625000 | D44: =C47 -> 549397.24 | E44: =D47 -> 469636.33 | F44: =E47 -> 385488.56 | G44: =F47 -> 296712.67 | H44: =G47 -> 203054.11 | I44: =H47 -> 104244.32
A45: Interest | C45: =C44*0.055 -> 34375 | D45: =D44*0.055 -> 30216.848 | E45: =E44*0.055 -> 25829.998 | F45: =F44*0.055 -> 21201.871 | G45: =G44*0.055 -> 16319.197 | H45: =H44*0.055 -> 11167.976 | I45: =I44*0.055 -> 5733.4378
A46: Principle | C46: =$B$42-C45 -> 75602.761 | D46: =$B$42-D45 -> 79760.913 | E46: =$B$42-E45 -> 84147.763 | F46: =$B$42-F45 -> 88775.89 | G46: =$B$42-G45 -> 93658.564 | H46: =$B$42-H45 -> 98809.785 | I46: =$B$42-I45 -> 104244.32
A47: Ending Balance | C47: =C44-C46 -> 549397.24 | D47: =D44-D46 -> 469636.33 | E47: =E44-E46 -> 385488.56 | F47: =F44-F46 -> 296712.67 | G47: =G44-G46 -> 203054.11 | H47: =H44-H46 -> 104244.32 | I47: =I44-I46 -> -2.3283064e-10
A50: NWC | B50: 650000 | C50: 650000 | D50: 650000 | E50: 650000 | F50: 650000 | G50: 650000 | H50: 650000 | I50: 0
A51: Change | B51: =B50 -> 650000 | C51: =(C50-B50) -> 0 | D51: =D50-C50 -> 0 | E51: =E50-D50 -> 0 | F51: =F50-E50 -> 0 | G51: =G50-F50 -> 0 | H51: =H50-G50 -> 0 | I51: =I50-H50 -> -650000
A52: -change | B52: =-B51 -> -650000 | C52: =-C51 -> 0 | D52: =-D51 -> 0 | E52: =-E51 -> 0 | F52: =-F51 -> 0 | G52: =-G51 -> 0 | H52: =-H51 -> 0 | I52: =-I51 -> 650000

Sheet Thermowell FCFFs Graphed
A1: Year | B1: Y0 | C1: Y1 | D1: Y2 | E1: Y3 | F1: Y4 | G1: Y5
A2: FCFF | B2: -1250000 | C2: -927500 | D2: -605000 | E2: -282500 | F2: 40000 | G2: 362500

Sheet Burton WACC
A10: Risk Free Rate | B10: 0.03 | C10: Long term Treasury rate
A11: MRP | B11: 0.058 | C11: Expected return on stock market - long term Treasury rate
B13: Unl Beta | C13: Lev Beta | D13: Mkt Cap
A14: TEL | B14: =C14/(1+'Exh. 4 Sensor Industry'!D21) -> 1.093204 | C14: ='Exh. 4 Sensor Industry'!D18 -> 1.235 | D14: ='Exh. 4 Sensor Industry'!$D$17 -> 33490.92 | F14: =D14/$D$18 -> 0.66139777 | G14: =F14*B14 -> 0.7230427
A15: AME | B15: =C15/(1+'Exh. 4 Sensor Industry'!H21) -> 1.1223599 | C15: ='Exh. 4 Sensor Industry'!H18 -> 1.246 | D15: ='Exh. 4 Sensor Industry'!$H$17 -> 16940.38 | F15: =D15/$D$18 -> 0.33454828 | G15: =F15*B15 -> 0.37548358
A16: OPS | B16: =C16/(1+'Exh. 4 Sensor Industry'!L21) -> 0.96368556 | C16: ='Exh. 4 Sensor Industry'!L18 -> 1.02 | D16: ='Exh. 4 Sensor Industry'!$L$17 -> 90.6692 | F16: =D16/$D$18 -> 0.001790587 | G16: =F16*B16 -> 0.0017255629
A17: CYBE | B17: =C17/(1+'Exh. 4 Sensor Industry'!P21) -> 0.85 | C17: ='Exh. 4 Sensor Industry'!P18 -> 0.85 | D17: ='Exh. 4 Sensor Industry'!$P$17 -> 114.609 | F17: =D17/$D$18 -> 0.0022633638 | G17: =F17*B17 -> 0.0019238593
A18: Industry Unl. Beta | B18: =SUMPRODUCT(B14:B17,D14:D17)/D18 -> 1.1021757 | C18: Use market cap of each (as a fraction of the total market cap of all 4) to compute weigted average industry unlevered beta | D18: =SUM(D14:D17) -> 50636.578 | G18: =SUM(G14:G17) -> 1.1021757
A19: Burton Levered | F19: Net Debt | G19: Mkt Cap | H19: Market (Net D)/E
A20: Industry Lev. Beta | B20: =B18*(1+H20) -> 2.0466816 | C20: Using Burton Market Value D/E | F20: ='Exh. 1 Burton BS'!D21+'Exh. 1 Burton BS'!D18+'Exh. 1 Burton BS'!D16-'Exh. 1 Burton BS'!D5 -> 6105.7458 | G20: =4.75*1500 -> 7125 | H20: =F20/G20 -> 0.85694679
A21: Burton CAPM Ke | B21: =B10+B20*B11 -> 0.14870753
A22: Kd | B22: ='Exh. 1 Burton BS'!D66 -> 0.055
A23: Tax Rate | B23: ='Exh. 2 Burton IS'!D34 -> 0.35
A24: Burton WACC | B24: =B21*(G20/(F20+G20))+B22*(1-B23)*(F20/(F20+G20)) -> 0.09657971
A32: Industry Unl. Beta | B32: =B18 -> 1.1021757 | I32: D/E | J32: 0.35
A33: Kd excl. 3% premium | B33: 0.054 | I33: Every $1 of E I have $0.35 D
A34: D% | B34: =I36/I34 -> 0.25925926 | I34: 1.35
A35: E% | B35: =I35/I34 -> 0.74074074 | I35: 1
A36: Lev. Beta | B36: =B32*I34 -> 1.4879372 | I36: 0.35
A37: Ke excl. 3% premium | B37: =J37+B36*J38 -> 0.11630036 | J37: 0.03
A38: WACC before Small Risk Premium | B38: =B35*B37+B33*(1-32%)*B34 -> 0.095668413 | J38: 0.058
A39: Small Risk Prem. | B39: 0.03
A40: Private WACC | B40: =B35*(B37+B39)+(B39+B33)*(1-32%)*B34 -> 0.12317952
A45: Unlevered Beta | B45: 1
A46: Tax Rate | B46: 0.25
A47: Risk Free Rate | B47: 0.035
A48: Mkt Risk Premium | B48: 0.06
A50: Scenario | B50: Mkt D/E | C50: Kd | D50: WACC | F50: Levered Beta | G50: Ke | H50: E | I50: D | J50: D+E | K50: D% | L50: E%
A51: 1 | B51: 0 | C51: 0.04 | D51: =G51*L51+C51*(1-$B$46)*K51 -> 0.095 | F51: =$B$45*(1+B51) -> 1 | G51: =$B$47+F51*$B$48 -> 0.095 | H51: 1 | I51: 0 | J51: =H51+I51 -> 1 | K51: =I51/J51 -> 0 | L51: =H51/J51 -> 1
A52: 2 | B52: =B51+0.1 -> 0.1 | C52: 0.041 | D52: =G52*L52+C52*(1-$B$46)*K52 -> 0.094613636 | F52: =$B$45*(1+B52) -> 1.1 | G52: =$B$47+F52*$B$48 -> 0.101 | H52: 1 | I52: 0.1 | J52: =H52+I52 -> 1.1 | K52: =I52/J52 -> 0.090909091 | L52: =H52/J52 -> 0.90909091
A53: 3 | B53: =B52+0.1 -> 0.2 | C53: 0.043 | D53: =G53*L53+C53*(1-$B$46)*K53 -> 0.094541667 | F53: =$B$45*(1+B53) -> 1.2 | G53: =$B$47+F53*$B$48 -> 0.107 | H53: 1 | I53: 0.2 | J53: =H53+I53 -> 1.2 | K53: =I53/J53 -> 0.16666667 | L53: =H53/J53 -> 0.83333333
A54: 4 | B54: =B53+0.1 -> 0.3 | C54: 0.055 | D54: =G54*L54+C54*(1-$B$46)*K54 -> 0.096442308 | F54: =$B$45*(1+B54) -> 1.3 | G54: =$B$47+F54*$B$48 -> 0.113 | H54: 1 | I54: 0.3 | J54: =H54+I54 -> 1.3 | K54: =I54/J54 -> 0.23076923 | L54: =H54/J54 -> 0.76923077
A55: 5 | B55: =B54+0.1 -> 0.4 | C55: 0.07 | D55: =G55*L55+C55*(1-$B$46)*K55 -> 0.1 | F55: =$B$45*(1+B55) -> 1.4 | G55: =$B$47+F55*$B$48 -> 0.119 | H55: 1 | I55: 0.4 | J55: =H55+I55 -> 1.4 | K55: =I55/J55 -> 0.28571429 | L55: =H55/J55 -> 0.71428571
A56: 6 | B56: =B55+0.1 -> 0.5 | C56: 0.08 | D56: =G56*L56+C56*(1-$B$46)*K56 -> 0.10333333 | F56: =$B$45*(1+B56) -> 1.5 | G56: =$B$47+F56*$B$48 -> 0.125 | H56: 1 | I56: 0.5 | J56: =H56+I56 -> 1.5 | K56: =I56/J56 -> 0.33333333 | L56: =H56/J56 -> 0.66666667
A57: 7 | B57: =B56+0.1 -> 0.6 | C57: 0.09 | D57: =G57*L57+C57*(1-$B$46)*K57 -> 0.1071875 | F57: =$B$45*(1+B57) -> 1.6 | G57: =$B$47+F57*$B$48 -> 0.131 | H57: 1 | I57: 0.6 | J57: =H57+I57 -> 1.6 | K57: =I57/J57 -> 0.375 | L57: =H57/J57 -> 0.625
A58: 8 | B58: =B57+0.1 -> 0.7 | C58: 0.1 | D58: =G58*L58+C58*(1-$B$46)*K58 -> 0.11147059 | F58: =$B$45*(1+B58) -> 1.7 | G58: =$B$47+F58*$B$48 -> 0.137 | H58: 1 | I58: 0.7 | J58: =H58+I58 -> 1.7 | K58: =I58/J58 -> 0.41176471 | L58: =H58/J58 -> 0.58823529
A59: 9 | B59: =B58+0.1 -> 0.8 | C59: 0.12 | D59: =G59*L59+C59*(1-$B$46)*K59 -> 0.11944444 | F59: =$B$45*(1+B59) -> 1.8 | G59: =$B$47+F59*$B$48 -> 0.143 | H59: 1 | I59: 0.8 | J59: =H59+I59 -> 1.8 | K59: =I59/J59 -> 0.44444444 | L59: =H59/J59 -> 0.55555556
A61: Optimal D/E | B61: =B53 -> 0.2 | C61: Select D/E from above (WACC miminimizing D/E)

Sheet Burton M&A Deals
B5: 2016 | C5: 2016 | D5: 2016
A6: 000's | B6: Burton | C6: EE | D6: Burton&EE
A7: Assets | B7: ='Exh. 1 Burton BS'!D12 -> 10081.978 | C7: ='Exh. 5 EE BS'!D12 -> 2017.1408 | D7: =C7+B7+M8 -> 17536.515
A8: Liabilities | B8: ='Exh. 1 Burton BS'!D22 -> 8536.5047 | C8: ='Exh. 5 EE BS'!D17 -> 587.54467 | D8: =C8+B8 -> 9124.0494 | M8: =6867-C9 -> 5437.3955
A9: Equity | B9: ='Exh. 1 Burton BS'!D24 -> 1545.4718 | C9: ='Exh. 5 EE BS'!D19 -> 1429.6045 | D9: =B9+6867 -> 8412.4718
A10: L&E | B10: =+B9+B8 -> 10081.977 | C10: =+C9+C8 -> 2017.1491 | D10: =D9+D8 -> 17536.521
A11: Shares | B11: 1500 | D11: =B11+(6867/4.75) -> 2945.6842
D16: Covenant | E16: Burton 2016 Before | F16: 2016 After
A17: =A25 -> Bank loan / (receivables + inventory) | D17: <.75 | E17: ='Exh. 1 Burton BS'!$D$16/('Exh. 1 Burton BS'!$D$6+'Exh. 1 Burton BS'!$D$7) -> 0.96387822 | F17: =('Exh. 1 Burton BS'!D16+'Exh. 5 EE BS'!D14)/('Exh. 1 Burton BS'!D6+'Exh. 1 Burton BS'!D7+'Exh. 5 EE BS'!D6+'Exh. 5 EE BS'!D7) -> 0.82718216 | G17: Bank Covenant
A18: =A26 -> Liabilities / book equity | D18: <3.0x | E18: ='Exh. 1 Burton BS'!$D$22/'Exh. 1 Burton BS'!$D$24 -> 5.523559 | F18: =('Exh. 1 Burton BS'!D22+'Exh. 5 EE BS'!D17)/('Exh. 1 Burton BS'!D24+6867+'Exh. 5 EE BS'!D19-C9) -> 1.084586 | G18: Bank Covenant
A19: =A27 -> Total interest-bearing debt / book equity | D19: <1.0x | E19: =('Exh. 1 Burton BS'!$D$16+'Exh. 1 Burton BS'!$D$18+'Exh. 1 Burton BS'!$D$21)/'Exh. 1 Burton BS'!$D$24 -> 4.1476007 | F19: =('Exh. 1 Burton BS'!D16+'Exh. 1 Burton BS'!D18+'Exh. 5 EE BS'!D14+'Exh. 1 Burton BS'!D21)/('Exh. 1 Burton BS'!D24+6867) -> 0.79888529 | G19: Marshal's Target
J22: =450000*3.5 -> 1575000 | K22: =1575 -> 1575
J23: =50000*3.5 -> 175000
D24: Covenant | E24: 2016 Before | F24: 2016 After | J24: =J23+J22 -> 1750000 | K24: =1750 -> 1750
A25: ='Exh. 1 Burton BS'!A27 -> Bank loan / (receivables + inventory) | D25: <.75 | E25: ='Exh. 1 Burton BS'!$D$16/('Exh. 1 Burton BS'!$D$6+'Exh. 1 Burton BS'!$D$7) -> 0.96387822 | F25: =('Exh. 1 Burton BS'!D16-'Burton M&A Deals'!K22)/('Exh. 1 Burton BS'!D6+'Exh. 1 Burton BS'!D7) -> 0.63241355 | G25: Bank Covenant
A26: ='Exh. 1 Burton BS'!A28 -> Liabilities / book equity | D26: <3.0x | E26: ='Exh. 1 Burton BS'!$D$22/'Exh. 1 Burton BS'!$D$24 -> 5.523559 | F26: =('Exh. 1 Burton BS'!D22-'Burton M&A Deals'!K22)/('Burton M&A Deals'!K24+'Exh. 1 Burton BS'!D24) -> 2.1124455 | G26: Bank Covenant
A27: ='Exh. 1 Burton BS'!A29 -> Total interest-bearing debt / book equity | D27: <1.0x | E27: =('Exh. 1 Burton BS'!$D$16+'Exh. 1 Burton BS'!$D$18+'Exh. 1 Burton BS'!$D$21)/'Exh. 1 Burton BS'!$D$24 -> 4.1476007 | F27: =('Exh. 1 Burton BS'!D16+'Exh. 1 Burton BS'!D18+'Exh. 1 Burton BS'!D21-'Burton M&A Deals'!K22)/('Exh. 1 Burton BS'!D24+'Burton M&A Deals'!K24) -> 1.4671647 | G27: Marshal's Target
D34: Covenant | E34: 2016 Before | F34: 2016 After | J34: 1250000 | K34: 1250
A35: =A25 -> Bank loan / (receivables + inventory) | D35: <.75 | E35: ='Exh. 1 Burton BS'!$D$16/('Exh. 1 Burton BS'!$D$6+'Exh. 1 Burton BS'!$D$7) -> 0.96387822 | F35: =('Exh. 1 Burton BS'!D16+'Burton M&A Deals'!K34)/('Exh. 1 Burton BS'!D6+'Exh. 1 Burton BS'!D7+K35) -> 1.0793023 | G35: Bank Covenant | J35: 650000 | K35: 650
A36: =A26 -> Liabilities / book equity | D36: <3.0x | E36: ='Exh. 1 Burton BS'!$D$22/'Exh. 1 Burton BS'!$D$24 -> 5.523559 | F36: =(K34+'Exh. 1 Burton BS'!D22)/('Exh. 1 Burton BS'!D24) -> 6.3323735 | G36: Bank Covenant | K36: 600
A37: =A27 -> Total interest-bearing debt / book equity | D37: <1.0x | E37: =('Exh. 1 Burton BS'!$D$16+'Exh. 1 Burton BS'!$D$18+'Exh. 1 Burton BS'!$D$21)/'Exh. 1 Burton BS'!$D$24 -> 4.1476007 | F37: =(K34+'Exh. 1 Burton BS'!D16+'Exh. 1 Burton BS'!D18+'Exh. 1 Burton BS'!D21)/'Exh. 1 Burton BS'!D24 -> 4.9564152 | G37: Marshal's Target
K40: 10543.43
K41: 2.96
K42: 0.0966
A44: Offer Price | B44: 3.5 | C44: per share
A45: Valuation / Share | B45: =K41 -> 2.96 | C45: per share | D45: Note: This is the valuation using the FCFFs from topic 4 solution and WACC from problem #2 in this assignment.
A46: NPV (thousands) | B46: =(B44-B45)*450-(50*B45) -> 95 | C46: in thousands | D46: Note: The NPV of a stock issuance compares the offer price of the issued shares and the valuation of the stock (or sometimes the market price)
B54: Marshal % | C54: EE % | J54: 1500000 | K54: 450000 | L54: 50000 | M54: =L54+K54+J54 -> 2000000
A55: A. % After Stock | B55: =J54/(J54+K54+L54) -> 0.75 | C55: N/A | J55: =6867000/4.75 -> 1445684.2
A56: B. % After EE | B56: =J54/J56 -> 0.50921955 | C56: =J55/J56 -> 0.49078045 | J56: =J55+J54 -> 2945684.2
A57: C. % After EE&Stock | B57: =J54/J57 -> 0.43532718 | C57: =J55/J57 -> 0.41956376 | J57: =J56+K54+L54 -> 3445684.2
A62: =NPV('Burton WACC'!B24,'Burton Thermowell'!$C$22:$I$22)-1250000 -> 678807.16 | B62: Thermowell FCFF NPV @ WACC
A69: 2021 | B69: <= Answer (List year 2017, 18, 19, 20, 21, or "Not in 5-year Horizon))
A70: Show Calculation here
H71: 1250
B72: 2017 | C72: 2018 | D72: 2019 | E72: 2020 | F72: 2021
A73: Fcff | B73: -86 | C73: 242 | D73: 709 | E73: 845 | F73: 896
A74: Interest | B74: ='Exh. 2 Burton IS'!E12*(1-0.35) -> 229.1575 | C74: ='Exh. 2 Burton IS'!F12*(1-0.35) -> 241.67 | D74: ='Exh. 2 Burton IS'!G12*(1-0.35) -> 241.67 | E74: ='Exh. 2 Burton IS'!H12*(1-0.35) -> 225.5825 | F74: ='Exh. 2 Burton IS'!I12*(1-0.35) -> 205.92
A75: FCFF - Interest | B75: =B73-B74 -> -315.1575 | C75: =C73-C74 -> 0.33 | D75: =D73-D74 -> 467.33 | E75: =E73-E74 -> 619.4175 | F75: =F73-F74 -> 690.08
A76: Cum. FCFF. | B76: =B75 -> -315.1575 | C76: =B76+C75 -> -314.8275 | D76: =C76+D75 -> 152.5025 | E76: =D76+E75 -> 771.92 | F76: =E76+F75 -> 1462

Sheet EE Acq NPV
A6: EE Value/Share | B6: =H34/'Exh. 6 EE IS'!D18 -> 4.8373786 | C6: Your EE valuation per share using discounted cash flow and EE WACC; show work below for credit
A7: Burton Value/Sh | B7: =+'Burton M&A Deals'!B45 -> 2.96 | C7: Your estimate using Assignment #4 FCFFs and Burton WACC from this assignment
A8: EE Offer Price | B8: =10*('Exh. 6 EE IS'!$D$13+'Exh. 6 EE IS'!$D$12+'Exh. 6 EE IS'!$D$11) -> 6866.5988 | C8: Based on EBITDA multiple provided in case and EE Income Statement
A9: EE Offer Price/Sh | B9: =+B8/'Exh. 6 EE IS'!D18 -> 6.2423625 | C9: EE Offer Price / EE Shares Outstanding
A10: Exchange Price | B10: 4.75 | C10: Burton stock price used to determine the number of Burton shares issued to EE for acquisition of EE
A11: Burton Shares Exchanged | B11: =+B8/B10 -> 1445.5997 | C11: EE Offer Price / Burton Stock Exchange Price
A12: EE Acquisition NPV | B12: =(B6-B9)*'Exh. 6 EE IS'!D18 -> -1545.4823 | C12: in Thousands; based on valuation and offer price of EE; =(EE Valuation/Sh - Offer/Sh)*Shares
A13: EE Exchange NPV | B13: =(B10-B7)*B11 -> 2587.6235 | C13: in Thousands; based on valuation and exchange price of Burton; = (Exchange Price - Burton Valuation/Sh)*(Burton Shares issued for EE Acquisition)
A14: EE Total NPV | B14: =+B13+B12 -> 1042.1412 | C14: in Thousands; = Acquisition NPV + Exchange NPV
A15: All-in NPV | B15: =+B14-0.09*B8 -> 424.14734 | C15: Total NPV above less 9% fees applied to deal value (EE offer price)
A17: Show Burton Valuation of EE Below for Credit: | I17: =B8/10 -> 686.65988
B25: 2017 | C25: 2018 | D25: 2019 | E25: 2020 | F25: 2021 | J25: 2014 | K25: 2015 | L25: =K25+1 -> 2016 | M25: 2017 | N25: 2018 | O25: 2019 | P25: 2020 | Q25: 2021
A26: EBIT | B26: =M28-M30-M31-M33 -> 848.59649 | C26: =N28-N30-N31-N33 -> 997.10087 | D26: =O28-O30-O31-O33 -> 1146.666 | E26: =P28-P30-P31-P33 -> 1284.2659 | F26: =Q28-Q30-Q31-Q33 -> 1412.6925 | I26: Net sales | J26: 2944.9224 | K26: 3566.301 | L26: 4072.7158 | M26: =L26*(1+M45) -> 5050.1676 | N26: =M26*(1+N45) -> 5933.9469 | O26: =N26*(1+O45) -> 6824.0389 | P26: =O26*(1+P45) -> 7642.9236 | Q26: =P26*(1+Q45) -> 8407.2159
A27: Tax | B27: =B26*0.35 -> 297.00877 | C27: =C26*0.35 -> 348.98531 | D27: =D26*0.35 -> 401.3331 | E27: =E26*0.35 -> 449.49307 | F27: =F26*0.35 -> 494.44238 | G27: Tax | H27: 0.35 | I27: COGS | J27: 1524.9562 | K27: 1811.6809 | L27: 2085.2305 | M27: =M26*M46 -> 2474.5821 | N27: =N26*N46 -> 2907.634 | O27: =O26*O46 -> 3343.7791 | P27: =P26*P46 -> 3745.0326 | Q27: =Q26*Q46 -> 4119.5358
A28: EBIT - Tax | B28: =B26-B27 -> 551.58772 | C28: =C26-C27 -> 648.11557 | D28: =D26-D27 -> 745.3329 | E28: =E26-E27 -> 834.77285 | F28: =F26-F27 -> 918.25014 | I28: Gross profit | J28: 1419.9662 | K28: 1754.6201 | L28: 1987.4853 | M28: =M26-M27 -> 2575.5855 | N28: =N26-N27 -> 3026.3129 | O28: =O26-O27 -> 3480.2598 | P28: =P26-P27 -> 3897.891 | Q28: =Q26-Q27 -> 4287.6801
A29: + Depr | B29: =+M33 -> 259.41027 | C29: =+N33 -> 304.80707 | D29: =+O33 -> 350.52813 | E29: =+P33 -> 392.59151 | F29: =+Q33 -> 431.85066
A30: - CAPEX | B30: =M78 -> 410.41028 | C30: =N78 -> 482.23208 | D30: =O78 -> 554.5669 | E30: =P78 -> 621.11492 | F30: =Q78 -> 683.22642 | I30: SG&A expense | J30: 814.86003 | K30: 930.09131 | L30: 1080.8988 | M30: =M26*M47 -> 1204.97 | N30: =N26*N47 -> 1415.8397 | O30: =O26*O47 -> 1628.2157 | P30: =P26*P47 -> 1823.6016 | Q30: =Q26*Q47 -> 2005.9617
A31: - Change in NWC | B31: =C43-B43 -> 332.20925 | C31: =D43-C43 -> 278.70781 | D31: =E43-D43 -> 280.69858 | E31: =F43-E43 -> 258.24269 | F31: =G43-F43 -> 241.02651 | I31: R&D expense | J31: 153.13596 | K31: 178.31505 | L31: 219.92665 | M31: =M48*M26 -> 262.60871 | N31: =N48*N26 -> 308.56524 | O31: =O48*O26 -> 354.85002 | P31: =P48*P26 -> 397.43203 | Q31: =Q48*Q26 -> 437.17523
A32: Terminal Value | F32: =B8 -> 6866.5988
A33: FCFF | B33: =B28+B29-B30-B31 -> 68.378458 | C33: =C28+C29-C30-C31 -> 191.98275 | D33: =D28+D29-D30-D31 -> 260.59556 | E33: =E28+E29-E30-E31 -> 348.00674 | F33: =F28+F29-F30-F31 -> 425.84787 | I33: Depreciation and amortization | J33: 142.23975 | K33: 196.85982 | L33: 206.07942 | M33: =M26*M49 -> 259.41027 | N33: =N26*N49 -> 304.80707 | O33: =O26*O49 -> 350.52813 | P33: =P26*P49 -> 392.59151 | Q33: =Q26*Q49 -> 431.85066
A34: FCFF + TV | B34: =B33 -> 68.378458 | C34: =C33 -> 191.98275 | D34: =D33 -> 260.59556 | E34: =E33 -> 348.00674 | F34: =F33+F32 -> 7292.4467 | G34: NPV | H34: =NPV(B49,B34:F34) -> 5321.1165 | I34: Interest expense | J34: 18.733 | K34: 18.733 | L34: 18.733 | M34: 18.733 | N34: 18.733 | O34: 18.733 | P34: 18.733 | Q34: 18.733
A36: NWC | B36: 2016 | C36: 2017 | D36: 2018 | E36: 2019 | F36: 2020 | G36: 2021 | I36: Pretax income (loss) | J36: 290.9975 | K36: 430.62093 | L36: 461.84746
A37: Cash | B37: =L53 -> 359.75383 | C37: =M53 -> 530.7003 | D37: =N53 -> 623.57285 | E37: =O53 -> 717.10878 | F37: =P53 -> 803.16183 | G37: =Q53 -> 883.47801
A38: Inventoey | B38: =L55 -> 480.58046 | C38: =M55 -> 553.83504 | D38: =N55 -> 650.75617 | E38: =O55 -> 748.3696 | F38: =P55 -> 838.17395 | G38: =Q55 -> 921.99135 | I38: Income taxes | J38: 101.84912 | K38: 150.71733 | L38: 161.64661
A39: Prepaid Exp | B39: =L56 -> 16.87364 | C39: =M56 -> 25.274586 | D39: =N56 -> 29.697639 | E39: =O56 -> 34.152285 | F39: =P56 -> 38.250559 | G39: =Q56 -> 42.075615 | I39: Net income | J39: 189.14837 | K39: 279.9036 | L39: 300.20085
A40: A/R | B40: =L54 -> 680.14353 | C40: =M54 -> 838.32781 | D40: =N54 -> 985.03518 | E40: =O54 -> 1132.7905 | F40: =P54 -> 1268.7253 | G40: =Q54 -> 1395.5978
A41: - A/P | B41: =L63 -> 175.12678 | C41: =M63 -> 217.1572 | D41: =N63 -> 255.15972 | E41: =O63 -> 293.43367 | F41: =P63 -> 328.64571 | G41: =Q63 -> 361.51029 | I41: Number of common shares (thousands) | J41: 1100 | K41: 1100 | L41: 1100
A42: - Accrued Expenses | B42: =L64 -> 101.81789 | C42: =M64 -> 138.36449 | D42: =N64 -> 162.57827 | E42: =O64 -> 186.96502 | F42: =P64 -> 209.40082 | G42: =Q64 -> 230.3409 | I42: Earnings per share | J42: =J39/J41 -> 0.17195307 | K42: =K39/K41 -> 0.25445782 | L42: =L39/L41 -> 0.27290986
A43: NWC | B43: =B37+B38+B39+B40-B41-B42 -> 1260.4068 | C43: =C37+C38+C39+C40-C41-C42 -> 1592.616 | D43: =D37+D38+D39+D40-D41-D42 -> 1871.3239 | E43: =E37+E38+E39+E40-E41-E42 -> 2152.0224 | F43: =F37+F38+F39+F40-F41-F42 -> 2410.2651 | G43: =G37+G38+G39+G40-G41-G42 -> 2651.2916 | I43: Cash dividend per share | J43: 0 | K43: 0 | L43: 0
A45: Industry Unlv Beta | B45: ='Burton WACC'!B18 -> 1.1021757 | I45: Sales Growth | M45: 0.24 | N45: 0.175 | O45: 0.15 | P45: 0.12 | Q45: 0.1
A46: Net Debt | B46: ='Exh. 5 EE BS'!D14-'Exh. 5 EE BS'!D5 -> -49.153834 | I46: COGS as % of Sales | L46: =L27/L26 -> 0.512 | M46: 0.49 | N46: 0.49 | O46: 0.49 | P46: 0.49 | Q46: 0.49
A47: Market Cap | B47: =B8+'Exh. 5 EE BS'!D5-'Exh. 5 EE BS'!D14 -> 6915.7526 | I47: SGA as % of Sales | L47: =L30/L26 -> 0.2654 | M47: 0.2386 | N47: 0.2386 | O47: 0.2386 | P47: 0.2386 | Q47: 0.2386
A48: D/E | B48: =B46/B47 -> -0.0071075177 | I48: RD as % | J48: =J31/J26 -> 0.052 | K48: =K31/K26 -> 0.05 | L48: =$L$31/$L$26 -> 0.054 | M48: 0.052 | N48: 0.052 | O48: 0.052 | P48: 0.052 | Q48: 0.052
A49: WACC | B49: =B50*B55+B56*(1-H27)*B54 -> 0.09388503 | I49: Depr | J49: =J33/J26 -> 0.0483 | K49: =K33/K26 -> 0.0552 | L49: =$L$33/$L$26 -> 0.0506 | M49: =AVERAGE($J$49:$L$49) -> 0.051366667 | N49: =AVERAGE($J$49:$L$49) -> 0.051366667 | O49: =AVERAGE($J$49:$L$49) -> 0.051366667 | P49: =AVERAGE($J$49:$L$49) -> 0.051366667 | Q49: =AVERAGE($J$49:$L$49) -> 0.051366667
A50: Ke | B50: =B52+B51*B53 -> 0.093471834 | I50: Tax | J50: =J38/J36 -> 0.35 | K50: =K38/K36 -> 0.35 | L50: =L38/L36 -> 0.35
A51: Levered Beta | B51: =B45*(1+B48) -> 1.094342
A52: Risk Free Rate | B52: 0.03 | J52: 2014 | K52: 2015 | L52: =K52+1 -> 2016 | M52: 2017 | N52: 2018 | O52: =N52+1 -> 2019 | P52: 2020 | Q52: 2021
A53: MRP | B53: 0.058 | I53: Cash and equivalents | J53: 379.09193 | K53: 350.20032 | L53: 359.75383 | M53: =$L$70*M26 -> 530.7003 | N53: =$L$70*N26 -> 623.57285 | O53: =$L$70*O26 -> 717.10878 | P53: =$L$70*P26 -> 803.16183 | Q53: =$L$70*Q26 -> 883.47801
A54: D% | B54: =B46/(B47+B46) -> -0.0071583961 | I54: Accounts receivable | J54: 485.9122 | K54: 592.00597 | L54: 680.14353 | M54: =$L$71*M26 -> 838.32781 | N54: =$L$71*N26 -> 985.03518 | O54: =$L$71*O26 -> 1132.7905 | P54: =$L$71*P26 -> 1268.7253 | Q54: =$L$71*Q26 -> 1395.5978
A55: E% | B55: =B47/(B47+B46) -> 1.0071584 | I55: Inventory | J55: 279.76763 | K55: 413.69092 | L55: 480.58046 | M55: =$L$72*M26 -> 553.83504 | N55: =$L$72*N26 -> 650.75617 | O55: =$L$72*O26 -> 748.3696 | P55: =$L$72*P26 -> 838.17395 | Q55: =$L$72*Q26 -> 921.99135
...

Sheet EE Acquisition
A2: combined financials if Burton acquires EE at the end of 2016 for $6.867 million cash by issuing additional Burton stock at a price of $4.75/share.
B3: 2016 | C3: 2016 | D3: 2016
A4: 000's | B4: Burton | C4: EE | D4: Burton&EE
A5: Assets | B5: 10082 | C5: 2017 | D5: 17537
A6: Liabilities | B6: 8537 | C6: 588 | D6: 9124
A7: Equity | B7: 1545 | C7: 1430 | D7: 8412
A8: L&E | B8: 10082 | C8: 2017 | D8: 17537
A9: Shares | B9: 1500 | D9: 2946
A11: The impact of Burton's EE acquisition on the bank covenants and Marshall's target
D12: Covenant | E12: Burton 2016 Before | F12: 2016 After
A13: Bank loan / (receivables + inventory) | D13: <.75 | E13: 0.96 | F13: 0.83 | G13: Bank Covenant
A14: Liabilities / book equity | D14: <3.0x | E14: 5.5x | F14: 1.1x | G14: Bank Covenant
A15: Total interest-bearing debt / book equity | D15: <1.0x | E15: 4.1x | F15: 0.80x | G15: Marshal's Target
C20: Burton | D20: Burton, EE, Thermowells, Stock
B21: Assets | C21: 10082 | D21: 17570
B22: Liabilities | C22: 8537 | D22: 7549
B23: Equity | C23: 1545 | D23: 10020

Sheet Stock Issuance
C2: 1 | D2: 2 | E2: 3 | F2: 4 | G2: 5 | H2: 6
B3: A/R | C3: 2315 | D3: 2825 | E3: 3,277 | F3: 3,539 | G3: 3,751 | H3: 3,977
B4: Inventory | C4: 2436 | D4: 2,998 | E4: 3,478 | F4: 3,756 | G4: 3,981 | H4: 4,220
B5: A/P | C5: -1153 | D5: -1384 | E5: -1605 | F5: -1733 | G5: -1837 | H5: -1948
B6: Accrued Expenses | C6: -567 | D6: -715 | E6: -829 | F6: -896 | G6: -949 | H6: -1006
B7: Non-cash NWC | C7: 3031 | D7: 3724 | E7: 4320 | F7: 4666 | G7: 4946 | H7: 5243
B8: FCFF + Terminal Value | C8: X | D8: -86 | E8: 242 | F8: 709 | G8: 845 | H8: 14750
D9: =D8/(1+$C$17)^C2 -> -78.42422 | E9: =E8/(1+$C$17)^D2 -> 201.24212 | F9: =F8/(1+$C$17)^E2 -> 537.6523 | G9: =G8/(1+$C$17)^F2 -> 584.33748 | H9: =H8/(1+$C$17)^G2 -> 9301.4534
B10: Enterprise Value | C10: =SUM(D9:H9) -> 10546.261
B11: Net Debt | C11: 6410
B12: Cash | C12: 304
B13: Equity Value | C13: =C10-C11+C12 -> 4440.261
B14: Shares Outstand. | C14: 1500
B15: Stock Valuation per Share | C15: =C13/C14 -> 2.960174
B16: Offer price | C16: 3.5
B17: WACC | C17: 0.0966
B18: NPV | C18: =(C16-C15)*450-50*C15 -> 94.912987

Sheet Exh. 1 Burton BS
A1: Exhibit 1
A2: Burton Sensors Consolidated Balance Sheets (Actual/Projected), 2014-2021 (Fiscal years ending December 31; U.S. $000s)
B4: 42004 | C4: =EOMONTH(B4,12) -> 42369 | D4: =EOMONTH(C4,12) -> 42735 | E4: =EOMONTH(D4,12) -> 43100 | F4: =EOMONTH(E4,12) -> 43465 | G4: =EOMONTH(F4,12) -> 43830 | H4: =EOMONTH(G4,12) -> 44196 | I4: =EOMONTH(H4,12) -> 44561
A5: Cash and equivalents | B5: ='Exh. 3 Burton SOCF'!B31 -> 279.6702 | C5: ='Exh. 3 Burton SOCF'!C31 -> 251.30362 | D5: ='Exh. 3 Burton SOCF'!D31 -> 304.25415 | E5: ='Exh. 3 Burton SOCF'!E31 -> 371.27018 | F5: ='Exh. 3 Burton SOCF'!F31 -> 359.69695 | G5: ='Exh. 3 Burton SOCF'!G31 -> 368.62282 | H5: ='Exh. 3 Burton SOCF'!H31 -> 437.50648 | I5: ='Exh. 3 Burton SOCF'!I31 -> 484.5569
A6: Accounts receivable | B6: =B35*B39 -> 1552.5405 | C6: =C35*C39 -> 1894.036 | D6: =D35*D39 -> 2315.3772 | E6: =E35*E39 -> 2824.9462 | F6: =F35*F39 -> 3276.9376 | G6: =G35*G39 -> 3539.0926 | H6: =H35*H39 -> 3751.4381 | I6: =I35*I39 -> 3976.5244 | J6: (24.5% of projected sales)
A7: Inventory | B7: =B35*B40 -> 1672.9416 | C7: =C35*C40 -> 2096.6901 | D7: =D35*D40 -> 2436.2604 | E7: =E35*E40 -> 2997.9021 | F7: =F35*F40 -> 3477.5664 | G7: =G35*G40 -> 3755.7717 | H7: =H35*H40 -> 3981.118 | I7: =I35*I40 -> 4219.9851 | J7: (26% of projected sales)
A8: Other current assets | B8: =B35*B44 -> 253.476 | C8: =C35*C44 -> 311.77548 | D8: =D35*D44 -> 371.94815 | E8: =E35*E44 -> 461.2157 | F8: =F35*F44 -> 535.01022 | G8: =G35*G44 -> 577.81103 | H8: =H35*H44 -> 612.47969 | I8: =I35*I44 -> 649.22848 | J8: (4% of projected sales)
A9: Current assets | B9: =SUM(B5:B8) -> 3758.6283 | C9: =SUM(C5:C8) -> 4553.8052 | D9: =SUM(D5:D8) -> 5427.8399 | E9: =SUM(E5:E8) -> 6655.3341 | F9: =SUM(F5:F8) -> 7649.2111 | G9: =SUM(G5:G8) -> 8241.2981 | H9: =SUM(H5:H8) -> 8782.5423 | I9: =SUM(I5:I8) -> 9330.2949
A11: Net PP&E | B11: =B51 -> 3874.0108 | C11: =C51 -> 4293.3488 | D11: =D51 -> 4654.1385 | E11: =E51 -> 4847.8491 | F11: =F51 -> 4938.8008 | G11: =G51 -> 4875.2416 | H11: =H51 -> 4789.4944 | I11: =I51 -> 4698.6025
A12: Total assets | B12: =B9+B11 -> 7632.6391 | C12: =C9+C11 -> 8847.154 | D12: =D9+D11 -> 10081.978 | E12: =E9+E11 -> 11503.183 | F12: =F9+F11 -> 12588.012 | G12: =G9+G11 -> 13116.54 | H12: =H9+H11 -> 13572.037 | I12: =I9+I11 -> 14028.897
A14: Accounts payable | B14: =B35*B41 -> 773.1018 | C14: =C35*C41 -> 935.32644 | D14: =D35*D41 -> 1153.0393 | E14: =E35*E41 -> 1383.6471 | F14: =F35*F41 -> 1605.0306 | G14: =G35*G41 -> 1733.4331 | H14: =H35*H41 -> 1837.4391 | I14: =I35*I41 -> 1947.6854 | J14: (12% of projected sales)
A15: Accrued expenses | B15: =B35*B45 -> 418.2354 | C15: =C35*C45 -> 491.04638 | D15: =D35*D45 -> 567.22093 | E15: =E35*E45 -> 714.88434 | F15: =F35*F45 -> 829.26583 | G15: =G35*G45 -> 895.6071 | H15: =H35*H45 -> 949.34353 | I15: =I35*I45 -> 1006.3041 | J15: (6.2% of projected sales)
A16: Bank loans | B16: 3020 | C16: =B16+'Exh. 3 Burton SOCF'!C21 -> 3880 | D16: =C16+'Exh. 3 Burton SOCF'!D21 -> 4580 | E16: =D16+'Exh. 3 Burton SOCF'!E21 -> 5080 | F16: =E16+'Exh. 3 Burton SOCF'!F21 -> 5230 | G16: =F16+'Exh. 3 Burton SOCF'!G21 -> 4930 | H16: =G16+'Exh. 3 Burton SOCF'!H21 -> 4530 | I16: =H16+'Exh. 3 Burton SOCF'!I21 -> 4030
A17: Deferred taxes | B17: =B74 -> 351.9 | C17: =C74 -> 360.66618 | D17: =D74 -> 406.24451 | E17: =E74 -> 527.89574 | F17: =F74 -> 590.11921 | G17: =G74 -> 624.04956 | H17: =H74 -> 658.31487 | I17: =I74 -> 702.47238
A18: Long-term debt, current portion | B18: =B64 -> 150 | C18: =C64 -> 150 | D18: =D64 -> 150 | E18: =E64 -> 150 | F18: =F64 -> 150 | G18: =G64 -> 150 | H18: =H64 -> 150 | I18: =I64 -> 150
A19: Current Liabilities | B19: =SUM(B14:B18) -> 4713.2372 | C19: =SUM(C14:C18) -> 5817.039 | D19: =SUM(D14:D18) -> 6856.5047 | E19: =SUM(E14:E18) -> 7856.4272 | F19: =SUM(F14:F18) -> 8404.4157 | G19: =SUM(G14:G18) -> 8333.0898 | H19: =SUM(H14:H18) -> 8125.0975 | I19: =SUM(I14:I18) -> 7836.4619
A21: Long-term debt | B21: =B62 -> 1980 | C21: =C62 -> 1830 | D21: =D62 -> 1680 | E21: =E62 -> 1530 | F21: =F62 -> 1380 | G21: =G62 -> 1230 | H21: =H62 -> 1080 | I21: =I62 -> 930
A22: Total liabilities | B22: =SUM(B19:B21) -> 6693.2372 | C22: =SUM(C19:C21) -> 7647.039 | D22: =SUM(D19:D21) -> 8536.5047 | E22: =SUM(E19:E21) -> 9386.4272 | F22: =SUM(F19:F21) -> 9784.4157 | G22: =SUM(G19:G21) -> 9563.0898 | H22: =SUM(H19:H21) -> 9205.0975 | I22: =SUM(I19:I21) -> 8766.4619
A24: Shareholders' equity | B24: 939.4 | C24: =B24+'Exh. 2 Burton IS'!C16 -> 1200.1132 | D24: =C24+'Exh. 2 Burton IS'!D16 -> 1545.4718 | E24: =D24+'Exh. 2 Burton IS'!E16 -> 2116.7542 | F24: =E24+'Exh. 2 Burton IS'!F16 -> 2803.5944 | G24: =F24+'Exh. 2 Burton IS'!G16 -> 3553.4481 | H24: =G24+'Exh. 2 Burton IS'!H16 -> 4366.9374 | I24: =H24+'Exh. 2 Burton IS'!I16 -> 5262.4335
A25: Total liabilities and equity | B25: =B22+B24 -> 7632.6372 | C25: =C22+C24 -> 8847.1522 | D25: =D22+D24 -> 10081.977 | E25: =E22+E24 -> 11503.181 | F25: =F22+F24 -> 12588.01 | G25: =G22+G24 -> 13116.538 | H25: =H22+H24 -> 13572.035 | I25: =I22+I24 -> 14028.895
A27: Bank loan / (receivables + inventory) | B27: =B16/(B6+B7) -> 0.93629414 | C27: =C16/(C6+C7) -> 0.97225414 | D27: =$D$16/($D$6+$D$7) -> 0.96387822 | E27: =E16/(E6+E7) -> 0.87242528 | F27: =F16/(F6+F7) -> 0.77429816 | G27: =G16/(G6+G7) -> 0.67581792 | H27: =H16/(H6+H7) -> 0.58583474 | I27: =I16/(I6+I7) -> 0.4916727
A28: Liabilities / book equity | B28: =B22/B24 -> 7.125013 | C28: =C22/C24 -> 6.3719316 | D28: =$D$22/$D$24 -> 5.523559 | E28: =E22/E24 -> 4.4343492 | F28: =F22/F24 -> 3.4899541 | G28: =G22/G24 -> 2.6912141 | H28: =H22/H24 -> 2.1079069 | I28: =I22/I24 -> 1.665857
A29: Total interest-bearing debt / book equity | B29: =(B16+B18+B21)/B24 -> 5.4822227 | C29: =(C16+C18+C21)/C24 -> 4.8828729 | D29: =($D$16+$D$18+$D$21)/$D$24 -> 4.1476007 | E29: =(E16+E18+E21)/E24 -> 3.1935688 | F29: =(F16+F18+F21)/F24 -> 2.4111904 | G29: =(G16+G18+G21)/G24 -> 1.77574 | H29: =(H16+H18+H21)/H24 -> 1.3190022 | I29: =(I16+I18+I21)/I24 -> 0.97103364
A31: Tables below are not shown in case
A32: Working Capital Assumptions (U.S. $ thousands)
B33: 42004 | C33: =EOMONTH(B33,12) -> 42369 | D33: =EOMONTH(C33,12) -> 42735 | E33: =EOMONTH(D33,12) -> 43100 | F33: =EOMONTH(E33,12) -> 43465 | G33: =EOMONTH(F33,12) -> 43830 | H33: =EOMONTH(G33,12) -> 44196 | I33: =EOMONTH(H33,12) -> 44561
A34: Income Statement Metrics
A35: Revenue | B35: ='Exh. 2 Burton IS'!B5 -> 6336.9 | C35: ='Exh. 2 Burton IS'!C5 -> 7794.387 | D35: ='Exh. 2 Burton IS'!D5 -> 9298.7037 | E35: ='Exh. 2 Burton IS'!E5 -> 11530.393 | F35: ='Exh. 2 Burton IS'!F5 -> 13375.255 | G35: ='Exh. 2 Burton IS'!G5 -> 14445.276 | H35: ='Exh. 2 Burton IS'!H5 -> 15311.992 | I35: ='Exh. 2 Burton IS'!I5 -> 16230.712
A36: Cost of Goods Sold | B36: ='Exh. 2 Burton IS'!B6 -> 2686.8456 | C36: ='Exh. 2 Burton IS'!C6 -> 3359.3808 | D36: ='Exh. 2 Burton IS'!D6 -> 4035.6374 | E36: ='Exh. 2 Burton IS'!E6 -> 4958.0688 | F36: ='Exh. 2 Burton IS'!F6 -> 5751.3598 | G36: ='Exh. 2 Burton IS'!G6 -> 6211.4686 | H36: ='Exh. 2 Burton IS'!H6 -> 6584.1567 | I36: ='Exh. 2 Burton IS'!I6 -> 6979.2061
A38: Working Capital Ratios
A39: Accounts receivable (% Sales) | B39: 0.245 | C39: 0.243 | D39: 0.249 | E39: 0.245 | F39: 0.245 | G39: 0.245 | H39: 0.245 | I39: 0.245
A40: Inventory (% Sales) | B40: 0.264 | C40: 0.269 | D40: 0.262 | E40: 0.26 | F40: 0.26 | G40: 0.26 | H40: 0.26 | I40: 0.26
A41: Accounts payable (% Sales) | B41: 0.122 | C41: 0.12 | D41: 0.124 | E41: 0.12 | F41: 0.12 | G41: 0.12 | H41: 0.12 | I41: 0.12
A43: Other Activity Ratios
A44: Other Current Assets (% Sales) | B44: 0.04 | C44: 0.04 | D44: 0.04 | E44: =+AVERAGE(B44:D44) -> 0.04 | F44: =+E44 -> 0.04 | G44: =+F44 -> 0.04 | H44: =+G44 -> 0.04 | I44: =+H44 -> 0.04
A45: Accrued Expenses (% Sales) | B45: 0.066 | C45: 0.063 | D45: 0.061 | E45: 0.062 | F45: =+E45 -> 0.062 | G45: =+F45 -> 0.062 | H45: =+G45 -> 0.062 | I45: =+H45 -> 0.062
B47: 42004 | C47: =EOMONTH(B47,12) -> 42369 | D47: =EOMONTH(C47,12) -> 42735 | E47: =EOMONTH(D47,12) -> 43100 | F47: =EOMONTH(E47,12) -> 43465 | G47: =EOMONTH(F47,12) -> 43830 | H47: =EOMONTH(G47,12) -> 44196 | I47: =EOMONTH(H47,12) -> 44561
A48: PP&E (Beginning) | B48: 3618 | C48: =B51 -> 3874.0108 | D48: =C51 -> 4293.3488 | E48: =D51 -> 4654.1385 | F48: =E51 -> 4847.8491 | G48: =F51 -> 4938.8008 | H48: =G51 -> 4875.2416 | I48: =H51 -> 4789.4944
A49: Less: Depreciation | B49: =-B35*B53 -> -98.85564 | C49: =-C35*C53 -> -102.88591 | D49: =-D35*D53 -> -122.74289 | E49: =-E35*E53 -> -152.20118 | F49: =-F35*F53 -> -176.55337 | G49: =-G35*G53 -> -208.01197 | H49: =-H35*H53 -> -238.86708 | I49: =-I35*I53 -> -253.19911
A50: Add: CapEx & Purchase of PP&E | B50: =B35*B54 -> 354.8664 | C50: =C35*C54 -> 522.22393 | D50: =D35*D54 -> 483.53259 | E50: =E35*E54 -> 345.91178 | F50: =F35*F54 -> 267.50511 | G50: =G35*G54 -> 144.45276 | H50: =H35*H54 -> 153.11992 | I50: =I35*I54 -> 162.30712
...

Sheet Exh. 2 Burton IS
A1: Exhibit 2
A2: Burton Sensors Consolidated Income Statements (Actual/Projected), 2014-2021 (Fiscal years ending December 31; U.S. $000s)
B4: 42004 | C4: =EOMONTH(B4,12) -> 42369 | D4: =EOMONTH(C4,12) -> 42735 | E4: =EOMONTH(D4,12) -> 43100 | F4: =EOMONTH(E4,12) -> 43465 | G4: =EOMONTH(F4,12) -> 43830 | H4: =EOMONTH(G4,12) -> 44196 | I4: =EOMONTH(H4,12) -> 44561
A5: Net sales | B5: 6336.9 | C5: =B5*(1+C26) -> 7794.387 | D5: =C5*(1+D26) -> 9298.7037 | E5: =D5*(1+E26) -> 11530.393 | F5: =E5*(1+F26) -> 13375.255 | G5: =F5*(1+G26) -> 14445.276 | H5: =G5*(1+H26) -> 15311.992 | I5: =H5*(1+I26) -> 16230.712
A6: COGS | B6: =B5*B29 -> 2686.8456 | C6: =C5*C29 -> 3359.3808 | D6: =D5*D29 -> 4035.6374 | E6: =E5*E29 -> 4958.0688 | F6: =F5*F29 -> 5751.3598 | G6: =G5*G29 -> 6211.4686 | H6: =H5*H29 -> 6584.1567 | I6: =I5*I29 -> 6979.2061 | J6: (43% of projected sales)
A7: Gross profit | B7: =B5-B6 -> 3650.0544 | C7: =C5-C6 -> 4435.0062 | D7: =D5-D6 -> 5263.0663 | E7: =E5-E6 -> 6572.3238 | F7: =F5-F6 -> 7623.8956 | G7: =G5-G6 -> 8233.8072 | H7: =H5-H6 -> 8727.8357 | I7: =I5-I6 -> 9251.5058
A9: SG&A expense | B9: =B5*B30 -> 2230.5888 | C9: =C5*C30 -> 2790.3905 | D9: =D5*D30 -> 3263.845 | E9: =E5*E30 -> 4035.6374 | F9: =F5*F30 -> 4681.3394 | G9: =G5*G30 -> 5055.8465 | H9: =H5*H30 -> 5359.1973 | I9: =I5*I30 -> 5680.7492 | J9: (35% of projected sales)
A10: R&D expense | B10: =B5*B31 -> 697.059 | C10: =C5*C31 -> 857.38257 | D10: =D5*D31 -> 1022.8574 | E10: =E5*E31 -> 1153.0393 | F10: =F5*F31 -> 1337.5255 | G10: =G5*G31 -> 1444.5276 | H10: =H5*H31 -> 1531.1992 | I10: =I5*I31 -> 1623.0712 | J10: (10% of projected sales)
A11: Depreciation and amortization | B11: =-'Exh. 1 Burton BS'!B49 -> 98.85564 | C11: =-'Exh. 1 Burton BS'!C49 -> 102.88591 | D11: =-'Exh. 1 Burton BS'!D49 -> 122.74289 | E11: =-'Exh. 1 Burton BS'!E49 -> 152.20118 | F11: =-'Exh. 1 Burton BS'!F49 -> 176.55337 | G11: =-'Exh. 1 Burton BS'!G49 -> 208.01197 | H11: =-'Exh. 1 Burton BS'!H49 -> 238.86708 | I11: =-'Exh. 1 Burton BS'!I49 -> 253.19911
A12: Net interest expense (income)* | B12: ='Exh. 1 Burton BS'!B67 -> 247.5 | C12: ='Exh. 1 Burton BS'!C67 -> 283.25 | D12: ='Exh. 1 Burton BS'!D67 -> 322.3 | E12: ='Exh. 1 Burton BS'!E67 -> 352.55 | F12: ='Exh. 1 Burton BS'!F67 -> 371.8 | G12: ='Exh. 1 Burton BS'!G67 -> 371.8 | H12: ='Exh. 1 Burton BS'!H67 -> 347.05 | I12: ='Exh. 1 Burton BS'!I67 -> 316.8
A13: Pretax income (loss) | B13: =B7-SUM(B9:B12) -> 376.05096 | C13: =C7-SUM(C9:C12) -> 401.09718 | D13: =D7-SUM(D9:D12) -> 531.321 | E13: =E7-SUM(E9:E12) -> 878.89593 | F13: =F7-SUM(F9:F12) -> 1056.6773 | G13: =G7-SUM(G9:G12) -> 1153.6211 | H13: =H7-SUM(H9:H12) -> 1251.522 | I13: =I7-SUM(I9:I12) -> 1377.6863
A15: Income taxes | B15: =B13*B34 -> 131.61784 | C15: =C13*C34 -> 140.38401 | D15: =D13*D34 -> 185.96235 | E15: =E13*E34 -> 307.61357 | F15: =F13*F34 -> 369.83705 | G15: =G13*G34 -> 403.76739 | H15: =H13*H34 -> 438.0327 | I15: =I13*I34 -> 482.19021 | J15: (35% of projected EBT)
A16: Net income | B16: =B13-B15 -> 244.43312 | C16: =C13-C15 -> 260.71317 | D16: =D13-D15 -> 345.35865 | E16: =E13-E15 -> 571.28235 | F16: =F13-F15 -> 686.84023 | G16: =G13-G15 -> 749.85373 | H16: =H13-H15 -> 813.4893 | I16: =I13-I15 -> 895.49611
A18: Number of common shares (thousands) | B18: 1500 | C18: 1500 | D18: 1500 | E18: 1500 | F18: 1500 | G18: 1500 | H18: 1500 | I18: 1500
A19: Earnings per share | B19: =B16/B18 -> 0.16295542 | C19: =C16/C18 -> 0.17380878 | D19: =D16/D18 -> 0.2302391 | E19: =E16/E18 -> 0.3808549 | F19: =F16/F18 -> 0.45789349 | G19: =G16/G18 -> 0.49990249 | H19: =H16/H18 -> 0.5423262 | I19: =I16/I18 -> 0.59699741
A20: Cash dividend per share | B20: 0 | C20: 0 | D20: 0 | E20: 0 | F20: 0 | G20: 0 | H20: 0 | I20: 0
A21: * Burton pays an average of 5.5% interest on all interest bearing debt.
A23: Tables below are not shown in case
A24: Assumptions
B25: 42004 | C25: =EOMONTH(B25,12) -> 42369 | D25: =EOMONTH(C25,12) -> 42735 | E25: =EOMONTH(D25,12) -> 43100 | F25: =EOMONTH(E25,12) -> 43465 | G25: =EOMONTH(F25,12) -> 43830 | H25: =EOMONTH(G25,12) -> 44196 | I25: =EOMONTH(H25,12) -> 44561
A26: Revenue growth | C26: 0.23 | D26: 0.193 | E26: 0.24 | F26: 0.16 | G26: 0.08 | H26: 0.06 | I26: 0.06
A28: Items as a % of Revenue
A29: COGS | B29: 0.424 | C29: 0.431 | D29: 0.434 | E29: 0.43 | F29: 0.43 | G29: 0.43 | H29: 0.43 | I29: 0.43
A30: SG&A expense | B30: 0.352 | C30: 0.358 | D30: 0.351 | E30: 0.35 | F30: 0.35 | G30: 0.35 | H30: 0.35 | I30: 0.35
A31: R&D expense | B31: 0.11 | C31: 0.11 | D31: 0.11 | E31: 0.1 | F31: 0.1 | G31: 0.1 | H31: 0.1 | I31: 0.1
A34: Tax rate | B34: 0.35 | C34: 0.35 | D34: 0.35 | E34: 0.35 | F34: 0.35 | G34: 0.35 | H34: 0.35 | I34: 0.35
A35: Payout ratio | B35: =B20/B19 -> 0 | C35: =C20/C19 -> 0 | D35: =D20/D19 -> 0

Sheet Exh. 3 Burton SOCF
A1: Exhibit 3
A2: Burton Sensors Consolidated Statement of Cash Flows (Actual/Projected), 2014-2021 (Fiscal years ending December 31; U.S. $000s)
B4: 42004 | C4: =EOMONTH(B4,12) -> 42369 | D4: =EOMONTH(C4,12) -> 42735 | E4: =EOMONTH(D4,12) -> 43100 | F4: =EOMONTH(E4,12) -> 43465 | G4: =EOMONTH(F4,12) -> 43830 | H4: =EOMONTH(G4,12) -> 44196 | I4: =EOMONTH(H4,12) -> 44561
A5: Operating Activities
A6: Net income | B6: ='Exh. 2 Burton IS'!B16 -> 244.43312 | C6: ='Exh. 2 Burton IS'!C16 -> 260.71317 | D6: ='Exh. 2 Burton IS'!D16 -> 345.35865 | E6: ='Exh. 2 Burton IS'!E16 -> 571.28235 | F6: ='Exh. 2 Burton IS'!F16 -> 686.84023 | G6: ='Exh. 2 Burton IS'!G16 -> 749.85373 | H6: ='Exh. 2 Burton IS'!H16 -> 813.4893 | I6: ='Exh. 2 Burton IS'!I16 -> 895.49611
A7: Depreciation and amortization | B7: =-'Exh. 1 Burton BS'!B49 -> 98.85564 | C7: =-'Exh. 1 Burton BS'!C49 -> 102.88591 | D7: =-'Exh. 1 Burton BS'!D49 -> 122.74289 | E7: =-'Exh. 1 Burton BS'!E49 -> 152.20118 | F7: =-'Exh. 1 Burton BS'!F49 -> 176.55337 | G7: =-'Exh. 1 Burton BS'!G49 -> 208.01197 | H7: =-'Exh. 1 Burton BS'!H49 -> 238.86708 | I7: =-'Exh. 1 Burton BS'!I49 -> 253.19911
A8: Less: increase (decrease) in accounts receivable | B8: =--320 -> 320 | C8: ='Exh. 1 Burton BS'!C6-'Exh. 1 Burton BS'!B6 -> 341.49554 | D8: ='Exh. 1 Burton BS'!D6-'Exh. 1 Burton BS'!C6 -> 421.34118 | E8: ='Exh. 1 Burton BS'!E6-'Exh. 1 Burton BS'!D6 -> 509.56896 | F8: ='Exh. 1 Burton BS'!F6-'Exh. 1 Burton BS'!E6 -> 451.99139 | G8: ='Exh. 1 Burton BS'!G6-'Exh. 1 Burton BS'!F6 -> 262.15501 | H8: ='Exh. 1 Burton BS'!H6-'Exh. 1 Burton BS'!G6 -> 212.34555 | I8: ='Exh. 1 Burton BS'!I6-'Exh. 1 Burton BS'!H6 -> 225.08629
A9: Less: increase (decrease) in inventory | B9: 289.8 | C9: ='Exh. 1 Burton BS'!C7-'Exh. 1 Burton BS'!B7 -> 423.7485 | D9: ='Exh. 1 Burton BS'!D7-'Exh. 1 Burton BS'!C7 -> 339.57026 | E9: ='Exh. 1 Burton BS'!E7-'Exh. 1 Burton BS'!D7 -> 561.6417 | F9: ='Exh. 1 Burton BS'!F7-'Exh. 1 Burton BS'!E7 -> 479.66433 | G9: ='Exh. 1 Burton BS'!G7-'Exh. 1 Burton BS'!F7 -> 278.20531 | H9: ='Exh. 1 Burton BS'!H7-'Exh. 1 Burton BS'!G7 -> 225.3463 | I9: ='Exh. 1 Burton BS'!I7-'Exh. 1 Burton BS'!H7 -> 238.86708
A10: Less: increase (decrease) in other current assets | B10: 55.6 | C10: ='Exh. 1 Burton BS'!C8-'Exh. 1 Burton BS'!B8 -> 58.29948 | D10: ='Exh. 1 Burton BS'!D8-'Exh. 1 Burton BS'!C8 -> 60.172668 | E10: ='Exh. 1 Burton BS'!E8-'Exh. 1 Burton BS'!D8 -> 89.267555 | F10: ='Exh. 1 Burton BS'!F8-'Exh. 1 Burton BS'!E8 -> 73.794512 | G10: ='Exh. 1 Burton BS'!G8-'Exh. 1 Burton BS'!F8 -> 42.800817 | H10: ='Exh. 1 Burton BS'!H8-'Exh. 1 Burton BS'!G8 -> 34.668662 | I10: ='Exh. 1 Burton BS'!I8-'Exh. 1 Burton BS'!H8 -> 36.748782
A11: Add: increase (decrease) in accounts payable | B11: 120.3 | C11: ='Exh. 1 Burton BS'!C14-'Exh. 1 Burton BS'!B14 -> 162.22464 | D11: ='Exh. 1 Burton BS'!D14-'Exh. 1 Burton BS'!C14 -> 217.71282 | E11: ='Exh. 1 Burton BS'!E14-'Exh. 1 Burton BS'!D14 -> 230.60785 | F11: ='Exh. 1 Burton BS'!F14-'Exh. 1 Burton BS'!E14 -> 221.38354 | G11: ='Exh. 1 Burton BS'!G14-'Exh. 1 Burton BS'!F14 -> 128.40245 | H11: ='Exh. 1 Burton BS'!H14-'Exh. 1 Burton BS'!G14 -> 104.00599 | I11: ='Exh. 1 Burton BS'!I14-'Exh. 1 Burton BS'!H14 -> 110.24635
A12: Add: increase (decrease) in accrued expenses | B12: 30.2 | C12: ='Exh. 1 Burton BS'!C15-'Exh. 1 Burton BS'!B15 -> 72.810981 | D12: ='Exh. 1 Burton BS'!D15-'Exh. 1 Burton BS'!C15 -> 76.174544 | E12: ='Exh. 1 Burton BS'!E15-'Exh. 1 Burton BS'!D15 -> 147.66341 | F12: ='Exh. 1 Burton BS'!F15-'Exh. 1 Burton BS'!E15 -> 114.38149 | G12: ='Exh. 1 Burton BS'!G15-'Exh. 1 Burton BS'!F15 -> 66.341267 | H12: ='Exh. 1 Burton BS'!H15-'Exh. 1 Burton BS'!G15 -> 53.736426 | I12: ='Exh. 1 Burton BS'!I15-'Exh. 1 Burton BS'!H15 -> 56.960612
A13: Add: increase (decrease) in deferred taxes | B13: ='Exh. 1 Burton BS'!B74-'Exh. 1 Burton BS'!B71 -> -163.85216 | C13: ='Exh. 1 Burton BS'!C17-'Exh. 1 Burton BS'!B17 -> 8.7661765 | D13: ='Exh. 1 Burton BS'!D17-'Exh. 1 Burton BS'!C17 -> 45.578337 | E13: ='Exh. 1 Burton BS'!E17-'Exh. 1 Burton BS'!D17 -> 121.65122 | F13: ='Exh. 1 Burton BS'!F17-'Exh. 1 Burton BS'!E17 -> 62.223472 | G13: ='Exh. 1 Burton BS'!G17-'Exh. 1 Burton BS'!F17 -> 33.930348 | H13: ='Exh. 1 Burton BS'!H17-'Exh. 1 Burton BS'!G17 -> 34.265307 | I13: ='Exh. 1 Burton BS'!I17-'Exh. 1 Burton BS'!H17 -> 44.157512
A14: Operating activities - net cash flow | B14: =SUM(B6:B7)-SUM(B8:B10)+SUM(B11:B13) -> -335.4634 | C14: =SUM(C6:C7)-SUM(C8:C10)+SUM(C11:C13) -> -216.14265 | D14: =SUM(D6:D7)-SUM(D8:D10)+SUM(D11:D13) -> -13.516873 | E14: =SUM(E6:E7)-SUM(E8:E10)+SUM(E11:E13) -> 62.927805 | F14: =SUM(F6:F7)-SUM(F8:F10)+SUM(F11:F13) -> 255.93187 | G14: =SUM(G6:G7)-SUM(G8:G10)+SUM(G11:G13) -> 603.37864 | H14: =SUM(H6:H7)-SUM(H8:H10)+SUM(H11:H13) -> 772.00358 | I14: =SUM(I6:I7)-SUM(I8:I10)+SUM(I11:I13) -> 859.35753
A16: Investing Activities
A17: Less: capex | B17: =-'Exh. 1 Burton BS'!B50 -> -354.8664 | C17: =-'Exh. 1 Burton BS'!C50 -> -522.22393 | D17: =-'Exh. 1 Burton BS'!D50 -> -483.53259 | E17: =-'Exh. 1 Burton BS'!E50 -> -345.91178 | F17: =-'Exh. 1 Burton BS'!F50 -> -267.50511 | G17: =-'Exh. 1 Burton BS'!G50 -> -144.45276 | H17: =-'Exh. 1 Burton BS'!H50 -> -153.11992 | I17: =-'Exh. 1 Burton BS'!I50 -> -162.30712
A18: Investing activities - net cash flow | B18: =SUM(B17:B17) -> -354.8664 | C18: =SUM(C17:C17) -> -522.22393 | D18: =SUM(D17:D17) -> -483.53259 | E18: =SUM(E17:E17) -> -345.91178 | F18: =SUM(F17:F17) -> -267.50511 | G18: =SUM(G17:G17) -> -144.45276 | H18: =SUM(H17:H17) -> -153.11992 | I18: =SUM(I17:I17) -> -162.30712
A20: Financing Activities
A21: Add: changes in bank borrowings | B21: 800 | C21: 860 | D21: 700 | E21: 500 | F21: 150 | G21: -300 | H21: -400 | I21: -500
A22: Add: long-term debt net issuance | B22: =SUM('Exh. 1 Burton BS'!B59:B60) -> -150 | C22: =SUM('Exh. 1 Burton BS'!C59:C60) -> -150 | D22: =SUM('Exh. 1 Burton BS'!D59:D60) -> -150 | E22: =SUM('Exh. 1 Burton BS'!E59:E60) -> -150 | F22: =SUM('Exh. 1 Burton BS'!F59:F60) -> -150 | G22: =SUM('Exh. 1 Burton BS'!G59:G60) -> -150 | H22: =SUM('Exh. 1 Burton BS'!H59:H60) -> -150 | I22: =SUM('Exh. 1 Burton BS'!I59:I60) -> -150
A23: Add: net issuance of common stock | B23: 0 | C23: 0 | D23: 0 | E23: 0 | F23: 0 | G23: 0 | H23: 0 | I23: 0
A24: Less: cash dividend | B24: ='Exh. 2 Burton IS'!B20 -> 0 | C24: ='Exh. 2 Burton IS'!C20 -> 0 | D24: ='Exh. 2 Burton IS'!D20 -> 0 | E24: ='Exh. 2 Burton IS'!E20 -> 0 | F24: ='Exh. 2 Burton IS'!F20 -> 0 | G24: ='Exh. 2 Burton IS'!G20 -> 0 | H24: ='Exh. 2 Burton IS'!H20 -> 0 | I24: ='Exh. 2 Burton IS'!I20 -> 0
A25: Financing activities - net cash flow | B25: =SUM(B21:B24) -> 650 | C25: =SUM(C21:C24) -> 710 | D25: =SUM(D21:D24) -> 550 | E25: =SUM(E21:E24) -> 350 | F25: =SUM(F21:F24) -> 0 | G25: =SUM(G21:G24) -> -450 | H25: =SUM(H21:H24) -> -550 | I25: =SUM(I21:I24) -> -650
A27: Total net cash flow | B27: =B14+B18+B25 -> -40.3298 | C27: =C14+C18+C25 -> -28.366581 | D27: =D14+D18+D25 -> 52.950535 | E27: =E14+E18+E25 -> 67.016028 | F27: =F14+F18+F25 -> -11.573236 | G27: =G14+G18+G25 -> 8.9258773 | H27: =H14+H18+H25 -> 68.883659 | I27: =I14+I18+I25 -> 47.050415
A29: Beginning cash | B29: 320 | C29: =B31 -> 279.6702 | D29: =C31 -> 251.30362 | E29: =D31 -> 304.25415 | F29: =E31 -> 371.27018 | G29: =F31 -> 359.69695 | H29: =G31 -> 368.62282 | I29: =H31 -> 437.50648
A30: Change in cash | B30: =B27 -> -40.3298 | C30: =C27 -> -28.366581 | D30: =D27 -> 52.950535 | E30: =E27 -> 67.016028 | F30: =F27 -> -11.573236 | G30: =G27 -> 8.9258773 | H30: =H27 -> 68.883659 | I30: =I27 -> 47.050415
A31: Ending cash | B31: =SUM(B29:B30) -> 279.6702 | C31: =SUM(C29:C30) -> 251.30362 | D31: =SUM(D29:D30) -> 304.25415 | E31: =SUM(E29:E30) -> 371.27018 | F31: =SUM(F29:F30) -> 359.69695 | G31: =SUM(G29:G30) -> 368.62282 | H31: =SUM(H29:H30) -> 437.50648 | I31: =SUM(I29:I30) -> 484.5569

Sheet Exh. 4 Sensor Industry
A1: Exhibit 4
A2: Comparative Data on Four Publically Traded Sensor Manufacturers, 2014-2016 (U.S. $ millions)
B4: TE Connectivity (TEL) | F4: Ametek (AME) | J4: Opsens (OPS) | N4: Cyberoptics (CYBE)
B5: 2014 | C5: 2015 | D5: =C5+1 -> 2016 | F5: 2014 | G5: 2015 | H5: =G5+1 -> 2016 | J5: 2014 | K5: 2015 | L5: =K5+1 -> 2016 | N5: 2014 | O5: 2015 | P5: =O5+1 -> 2016
A7: Net sales | B7: 12233 | C7: 12238 | D7: 13113 | F7: 3974.295 | G7: 3840.087 | H7: 4300.17 | J7: 5.20723 | K7: 9.600817 | L7: 17.751996 | N7: 41.13 | O7: 66.24 | P7: 53.333
A8: Operating profit | B8: 1992 | C8: 1936 | D8: 2201 | F8: 944.316 | G8: 841.397 | H8: 931.894 | J8: -5.132 | K8: -8.492 | L8: -6.38 | N8: -2.2 | O8: 6.153 | P8: 1.015
A9: Net income | B9: 2420 | C9: 2009 | D9: 1683 | F9: 590.859 | G9: 512.158 | H9: 681.47 | J9: -2.884 | K9: -9.282 | L9: -6.537 | N9: -2.1 | O9: 11.562 | P9: 2
A10: Assets | B10: 20589 | C10: 17608 | D10: 19403 | F10: 6660.45 | G10: 7100.674 | H10: 7796.064 | J10: 12.763253 | K10: 16.861476 | L10: 27.609801 | N10: 44.739 | O10: 59.58 | P10: 59.501
A11: Total debt | B11: 3884 | C11: 4070 | D11: 4344 | F11: 1866.115 | G11: 2062.644 | H11: 1866.166 | J11: 3.69379 | K11: 5.577493 | L11: 5.298393 | N11: 0 | O11: 0 | P11: 0
A12: Total liabilities | B12: 11004 | C12: 9123 | D12: 9652 | F12: 3405.824 | G12: 3844.161 | H12: 3768.431 | J12: 6.869814 | K12: 9.549053 | L12: 9.644477 | N12: 8.681 | O12: 10.682 | P12: 7.219
A13: Shareholders' equity | B13: 9585 | C13: 8485 | D13: 9751 | F13: 3254.626 | G13: 3256.513 | H13: 4027.633 | J13: 5.893439 | K13: 7.312423 | L13: 17.965324 | N13: 36.058 | O13: 48.898 | P13: 52.282
A14: Operating margin | B14: =B8/B7 -> 0.16283822 | C14: =C8/C7 -> 0.15819578 | D14: =D8/D7 -> 0.1678487 | F14: =F8/F7 -> 0.23760592 | G14: =G8/G7 -> 0.21910884 | H14: =H8/H7 -> 0.21671097 | J14: =J8/J7 -> -0.98555278 | K14: =K8/K7 -> -0.88450806 | L14: =L8/L7 -> -0.35939621 | N14: =N8/N7 -> -0.053488938 | O14: =O8/O7 -> 0.092889493 | P14: =P8/P7 -> 0.019031369
A15: Profit margin | B15: =B9/B7 -> 0.19782555 | C15: =C9/C7 -> 0.16416081 | D15: =D9/D7 -> 0.12834592 | F15: =F9/F7 -> 0.14867014 | G15: =G9/G7 -> 0.13337146 | H15: =H9/H7 -> 0.15847513 | J15: =J9/J7 -> -0.55384533 | K15: =K9/K7 -> -0.96679272 | L15: =L9/L7 -> -0.36824028 | N15: =N9/N7 -> -0.051057622 | O15: =O9/O7 -> 0.1745471 | P15: =P9/P7 -> 0.037500234
A16: Shares outstanding | B16: 405 | C16: 366 | D16: 355 | F16: 239.906 | G16: 232.593 | H16: 230.229 | J16: 60.179119 | K16: 66.735651 | L16: 80.954643 | N16: 6.706 | O16: 6.832 | P16: 6.946
A17: Market capitalization | B17: 24959.14 | C17: 24618.77 | D17: 33490.92 | F17: 12748.27 | G17: 15280 | H17: 16940.38 | J17: 51.754042 | K17: 108.11175 | L17: 90.6692 | N17: 51.3009 | O17: 191.296 | P17: 114.609
A18: Equity beta* | B18: 1.295 | C18: 1.262 | D18: 1.235 | F18: 1.289 | G18: 1.158 | H18: 1.246 | J18: 1.315 | K18: 1.165 | L18: 1.02 | N18: 0.82 | O18: 0.8 | P18: 0.85
A19: EPS | B19: =B9/B16 -> 5.9753086 | C19: =C9/C16 -> 5.489071 | D19: =D9/D16 -> 4.7408451 | F19: =F9/F16 -> 2.4628771 | G19: =G9/G16 -> 2.2019493 | H19: =H9/H16 -> 2.9599659 | J19: =J9/J16 -> -0.0479236 | K19: =K9/K16 -> -0.13908608 | L19: =L9/L16 -> -0.08074892 | N19: =N9/N16 -> -0.3131524 | O19: =O9/O16 -> 1.6923302 | P19: =P9/P16 -> 0.2879355
