Workbook

Sheet Wrigley Model
D2: WM. WRIGLEY JR. COMPANY
D3: Financial Forecast for Wrigley, Synergy Calculation
D4: (in millions of dollars)
D6: Best Case | E6: Click left for different scenarios
C9: Financial Forecast & Free Cash Flow Calculation | O9: Synergies Assumptions & Case Scenarios
E11: 2006 | F11: 2007 | G11: 2008F | H11: 2009F | I11: 2010F | J11: 2011F | K11: 2012F | L11: Synergies | P11: Worst Case | Q11: Base Case | R11: Best Case
D13: Sugar prices (dollar/ton) | E13: 415.93865 | F13: 288.24346 | G13: 250 | H13: 254 | I13: 258 | J13: 263 | K13: 267
D14: Sugar (in millions of tons) | E14: 1.5947893 | F14: 2.638659 | G14: 2.9266176 | H14: 3.0203226 | I14: 3.1008421 | J14: 3.1791809 | K14: 3.2717057
C16: Income Statement Data
C17: Revenues by regions
D18: North America | E18: 1822.3488 | F18: 1823.2021 | G18: 2010.987 | H18: =(1+L18)*2096.321 -> 2180.1738 | I18: =(1+L18)*2182.5375 -> 2269.839 | J18: =(1+L18)*2265.291 -> 2355.9026 | K18: =(1+L18)*2353.0375 -> 2447.159 | L18: {=_xlfn.SWITCH($D$6,$P$11,P18,$Q$11,Q18,$R$11,R18)} -> 0.04 | P18: 0.03 | Q18: 0.035 | R18: 0.04
D19: EMEAI | E19: 2153.146 | F19: 2726.0155 | G19: 3079.89 | H19: =(1+L19)*3471.825 -> 3645.4162 | I19: =(1+L19)*3881.67 -> 4075.7535 | J19: =(1+L19)*4356.936 -> 4574.7828 | K19: =(1+L19)*4878.775 -> 5122.7137 | L19: {=_xlfn.SWITCH($D$6,$P$11,P19,$Q$11,Q19,$R$11,R19)} -> 0.05 | P19: 0.03 | Q19: 0.04 | R19: 0.05
D20: Asia | E20: 647.75233 | F20: 776.7438 | G20: 875.655 | H20: =(1+L20)*965.498 -> 1052.3928 | I20: =(1+L20)*1060.605 -> 1156.0595 | J20: =(1+L20)*1168.164 -> 1273.2988 | K20: =(1+L20)*1286.615 -> 1402.4104 | L20: {=_xlfn.SWITCH($D$6,$P$11,P20,$Q$11,Q20,$R$11,R20)} -> 0.09 | P20: 0.05 | Q20: 0.07 | R20: 0.09
D21: All other | E21: 62.76287 | F21: 63.138593 | G21: 72.468 | H21: =(1+L21)*79.356 -> 85.70448 | I21: =(1+L21)*90.1875 -> 97.4025 | J21: =(1+L21)*102.609 -> 110.81772 | K21: =(1+L21)*116.5725 -> 125.8983 | L21: {=_xlfn.SWITCH($D$6,$P$11,P21,$Q$11,Q21,$R$11,R21)} -> 0.08 | P21: 0.03 | Q21: 0.06 | R21: 0.08
C22: Revenues | E22: =SUM(E18:E21) -> 4686.01 | F22: =SUM(F18:F21) -> 5389.1 | G22: =SUM(G18:G21) -> 6039 | H22: =SUM(H18:H21) -> 6963.6874 | I22: =SUM(I18:I21) -> 7599.0545 | J22: =SUM(J18:J21) -> 8314.8019 | K22: =SUM(K18:K21) -> 9098.1814
C24: COGS
D25: Sugar | F25: =F13*F14 -> 760.5762 | G25: =G13*G14 -> 731.65441 | H25: =H13*H14*(0.317*(1+$L$18)+0.525*(1+$L$19)+0.146*(1+$L$20)+0.012*(1+$L$21)) -> 807.84453 | I25: =I13*I14*(0.3025*(1+$L$18)+0.538*(1+$L$19)+0.147*(1+$L$20)+0.0125*(1+$L$21)) -> 842.60218 | J25: =J13*J14*(0.287*(1+$L$18)+0.552*(1+$L$19)+0.148*(1+$L$20)+0.013*(1+$L$21)) -> 880.80707 | K25: =K13*K14*(0.2725*(1+$L$18)+0.565*(1+$L$19)+0.149*(1+$L$20)+0.0135*(1+$L$21)) -> 920.40239
D26: Other | F26: 1774.6778 | G26: 2046.96 | H26: =2278.33*(0.317*(1+$L$18)+0.525*(1+$L$19)+0.146*(1+$L$20)+0.012*(1+$L$21)) -> 2399.1498 | I26: =2515.26*(0.317*(1+$L$18)+0.525*(1+$L$19)+0.146*(1+$L$20)+0.012*(1+$L$21)) -> 2648.6442 | J26: =2794.5*(0.317*(1+$L$18)+0.525*(1+$L$19)+0.146*(1+$L$20)+0.012*(1+$L$21)) -> 2942.6923 | K26: =3097.76*(0.317*(1+$L$18)+0.525*(1+$L$19)+0.146*(1+$L$20)+0.012*(1+$L$21)) -> 3262.0342
C27: Total COGS | F27: =F25+F26 -> 2535.254 | G27: =G25+G26 -> 2778.6144 | H27: =H25+H26 -> 3206.9944 | I27: =I25+I26 -> 3491.2464 | J27: =J25+J26 -> 3823.4994 | K27: =K25+K26 -> 4182.4366
C29: SG&A | F29: 1891.074 | G29: 2113.65 | H29: =(1+L29)*2314.55*(0.317*(1+$L$18)+0.525*(1+$L$19)+0.146*(1+$L$20)+0.012*(1+$L$21)) -> 2071.697 | I29: =(1+L29)*2525.25*(0.317*(1+$L$18)+0.525*(1+$L$19)+0.146*(1+$L$20)+0.012*(1+$L$21)) -> 2260.2894 | J29: =(1+L29)*2754.657*(0.317*(1+$L$18)+0.525*(1+$L$19)+0.146*(1+$L$20)+0.012*(1+$L$21)) -> 2465.626 | K29: =(1+L29)*3004.98*(0.317*(1+$L$18)+0.525*(1+$L$19)+0.146*(1+$L$20)+0.012*(1+$L$21)) -> 2689.684 | L29: {=_xlfn.SWITCH($D$6,$P$11,P29,$Q$11,Q29,$R$11,R29)} -> -0.15 | P29: -0.075 | Q29: -0.1 | R29: -0.15
C31: Operating income | F31: =F22-F27-F30-F29 -> 962.772 | G31: =G22-G27-G30-G29 -> 1146.7356 | H31: =H22-H27-H30-H29 -> 1684.996 | I31: =I22-I27-I30-I29 -> 1847.5186 | J31: =J22-J27-J30-J29 -> 2025.6765 | K31: =K22-K27-K30-K29 -> 2226.0608
C33: Free Cash Flow Calculation
D34: NOPAT | F34: =F31*(1-$E$44) -> 654.68496 | G34: =G31*(1-$E$44) -> 779.7802 | H34: =H31*(1-$E$44) -> 1145.7973 | I34: =I31*(1-$E$44) -> 1256.3127 | J34: =J31*(1-$E$44) -> 1377.46 | K34: =K31*(1-$E$44) -> 1513.7214
D35: Depreciation | F35: 51.35 | G35: 192.86 | H35: 156.15 | I35: 158.32 | J35: 162.96 | K35: 160.34
D36: Cap X | F36: 188.9 | G36: 325 | H36: 340 | I36: 356 | J36: 373 | K36: 390
D37: Changes in NWC | F37: =F41-E41 -> -5.44 | G37: =G41-F41 -> 133.63996 | H37: =H41-G41 -> -11.801795 | I37: =I41-H41 -> 42.414938 | J37: =J41-I41 -> 52.357359 | K37: =K41-J41 -> 31.992812
C38: FCF | G38: =G34+G35-G36-G37 -> 514.00024 | H38: =H34+H35-H36-H37 -> 973.74909 | I38: =I34+I35-I36-I37 -> 1016.2177 | J38: =J34+J35-J36-J37 -> 1115.0627 | K38: =K34+K35-K36-K37 -> 1252.0685
C41: NWC | E41: =E22*E42 -> 454.098 | F41: =F22*F42 -> 448.658 | G41: =G22*G42 -> 582.29796 | H41: =H22*H42 -> 570.49617 | I41: =I22*I42 -> 612.91111 | J41: =J22*J42 -> 665.26846 | K41: =K22*K42 -> 697.26128 | L41: {=_xlfn.SWITCH($D$6,$P$11,P41,$Q$11,Q41,$R$11,R41)} -> -0.35 | P41: -0.2 | Q41: -0.25 | R41: -0.35
D42: NWC as percentage of sales | E42: 0.096905043 | F42: 0.083252862 | G42: 0.096422912 | H42: 0.081924437 | I42: 0.080656233 | J42: 0.08001014 | K42: 0.076637434
D44: Tax rate | E44: 0.32
C46: Discounted Cash Flow Analysis
C48: WACC | K48: ='DCF - Ex.11'!E90 -> 0.076672101
C50: Projected Period | G50: 1 | H50: 2 | I50: 3 | J50: 4 | K50: 5
D51: FCF | G51: =G38 -> 514.00024 | H51: =H38 -> 973.74909 | I51: =I38 -> 1016.2177 | J51: =J38 -> 1115.0627 | K51: =K38 -> 1252.0685
D52: Discount factor | G52: =1/(1+$K$48)^G50 -> 0.92878788 | H52: =1/(1+$K$48)^H50 -> 0.86264693 | I52: =1/(1+$K$48)^I50 -> 0.80121601 | J52: =1/(1+$K$48)^J50 -> 0.74415972 | K52: =1/(1+$K$48)^K50 -> 0.69116653
D53: Discounted FCF | G53: =G51*G52 -> 477.39719 | H53: =H51*H52 -> 840.00166 | I53: =I51*I52 -> 814.20991 | J53: =J51*J52 -> 829.78473 | K53: =K51*K52 -> 865.38787
D54: Present value (PP) | K54: =SUM(G53:K53) -> 3826.7814
C56: Terminal Value
D57: Growth rate | K57: 0.025
D58: TV | K58: =K51*(1+$K$57)/($K$48-$K$57) -> 24836.812
...

Sheet DCF - Ex.11
D2: Exhibit 11
D3: WM. WRIGLEY JR. COMPANY
D4: Financial Forecast for Wrigley, Stand-Alone Valuation
D5: (in millions of dollars)
E7: 2006 | F7: 2007 | G7: 2008F | H7: 2009F | I7: 2010F | J7: 2011F | K7: 2012F
C9: Financial Forecast & Free Cash Flow Calculation
D11: Sugar prices (dollar/ton) | E11: 415.93865 | F11: 288.24346 | G11: 250 | H11: 254 | I11: 258 | J11: 263 | K11: 267
D12: Sugar (in millions of tons) | E12: 1.5947893 | F12: 2.638659 | G12: 2.9266176 | H12: 3.0203226 | I12: 3.1008421 | J12: 3.1791809 | K12: 3.2717057
C14: Income Statement Data
C15: Revenues by regions
D16: North America | E16: 1822.3488 | F16: 1823.2021 | G16: 2010.987 | H16: 2096.321 | I16: 2182.5375 | J16: 2265.291 | K16: 2353.0375
D17: EMEAI | E17: 2153.146 | F17: 2726.0155 | G17: 3079.89 | H17: 3471.825 | I17: 3881.67 | J17: 4356.936 | K17: 4878.775
D18: Asia | E18: 647.75233 | F18: 776.7438 | G18: 875.655 | H18: 965.498 | I18: 1060.605 | J18: 1168.164 | K18: 1286.615
D19: All other | E19: 62.76287 | F19: 63.138593 | G19: 72.468 | H19: 79.356 | I19: 90.1875 | J19: 102.609 | K19: 116.5725
C20: Revenues | E20: 4686.01 | F20: 5389.1 | G20: 6039 | H20: 6613 | I20: 7215 | J20: 7893 | K20: 8635
C22: COGS
D23: Sugar | F23: 760.5762 | G23: 731.65441 | H23: 767.16194 | I23: 800.01726 | J23: 836.12457 | K23: 873.54542
D24: Other | F24: 1774.6778 | G24: 2046.96 | H24: 2278.33 | I24: 2515.26 | J24: 2794.5 | K24: 3097.76
C25: Total COGS | F25: 2535.254 | G25: 2778.6144 | H25: 3045.4919 | I25: 3315.2773 | J25: 3630.6246 | K25: 3971.3054
C27: SG&A | F27: 1891.074 | G27: 2113.65 | H27: 2314.55 | I27: 2525.25 | J27: 2754.657 | K27: 3004.98
C29: Operating income | F29: 962.772 | G29: 1146.7356 | H29: 1252.9581 | I29: 1374.4727 | J29: 1507.7184 | K29: 1658.7146
C31: Free Cash Flow Calculation
D32: NOPAT | F32: 654.68496 | G32: 779.7802 | H32: 852.01148 | I32: 934.64146 | J32: 1025.2485 | K32: 1127.9259
D33: Depreciation | F33: 51.352 | G33: 192.858 | H33: 156.152 | I33: 158.317 | J33: 162.963 | K33: 160.337
D34: CapEx | F34: 188.9 | G34: 325 | H34: 340 | I34: 356 | J34: 373 | K34: 390
D35: Changes in NWC | F35: -5.44 | G35: 133.63996 | H35: -40.531662 | I35: 40.16842 | J35: 49.585314 | K35: 30.244208
C36: FCF | G36: 513.99824 | H36: 708.69515 | I36: 696.79004 | J36: 765.62622 | K36: 868.01871
C38: Net PPE | E38: 1422.516 | F38: 1560.064 | G38: 1692.206 | H38: 1876.054 | I38: 2073.737 | J38: 2283.774 | K38: 2513.437
D39: Net PPE as percentage of sales | E39: 0.30356657 | F39: 0.28948507 | G39: 0.28021295 | H39: 0.28369182 | I39: 0.28742024 | J39: 0.2893417 | K39: 0.29107551
C40: NWC | E40: 454.098 | F40: 448.658 | G40: 582.29796 | H40: 541.7663 | I40: 581.93472 | J40: 631.52003 | K40: 661.76424
D41: NWC as percentage of sales | E41: 0.096905043 | F41: 0.083252862 | G41: 0.096422912 | H41: 0.081924437 | I41: 0.080656233 | J41: 0.08001014 | K41: 0.076637434
C44: Discounted Cash Flow Analysis
C46: WACC | K46: =E90 -> 0.076672101
C48: Projected Period | G48: 1 | H48: 2 | I48: 3 | J48: 4 | K48: 5
D49: FCF | G49: =G36 -> 513.99824 | H49: =H36 -> 708.69515 | I49: =I36 -> 696.79004 | J49: =J36 -> 765.62622 | K49: =K36 -> 868.01871
D50: Discount factor | G50: =1/(1+$K$46)^G48 -> 0.92878788 | H50: =1/(1+$K$46)^H48 -> 0.86264693 | I50: =1/(1+$K$46)^I48 -> 0.80121601 | J50: =1/(1+$K$46)^J48 -> 0.74415972 | K50: =1/(1+$K$46)^K48 -> 0.69116653
D51: Discounted FCF | G51: =G49*G50 -> 477.39533 | H51: =H49*H50 -> 611.35369 | I51: =I49*I50 -> 558.27934 | J51: =J49*J50 -> 569.74819 | K51: =K49*K50 -> 599.94548
D52: Present value (PP) | K52: =SUM(G51:K51) -> 2816.722
C54: Terminal Value
D55: Growth rate | K55: 0.025
...

Sheet Comparables - Ex.10
D2: Exhibit 10
D3: WM. WRIGLEY JR. COMPANY
D4: Confectionery Industry at the Beginning of 2008
D5: (in millions of dollars)
D8: Confectionary Industry Data
E10: Revenues | F10: Operating Margin | G10: Net Income | H10: EBIT | I10: LT Debt | J10: Current Assets | K10: Current Liabilities | L10: Employees
D11: Cadbury plc | E11: 15855 | F11: 0.13169347 | G11: 1567 | H11: 2088 | I11: 2383 | J11: 5171 | K11: 9178 | L11: 36460
D12: Kraft Foods Inc. | E12: 37000 | F12: 0.165 | G12: 2850 | H12: 6105 | I12: 10600 | J12: 9544 | K12: 10194 | L12: 90000
D13: Lance, Inc. | E13: 765 | F13: 0.09 | G13: 25 | H13: 68.85 | I13: 50 | J13: 141.8 | K13: 76.5 | L13: 4800
D14: The Hershey Company | E14: 4947 | F14: 0.24 | G14: 480 | H14: 1187.28 | I14: 1280 | J14: 1426.6 | K14: 1618.8 | L14: 12800
D15: Tootsie Roll Industries, Inc. | E15: 493 | F15: 0.2 | G15: 55 | H15: 98.6 | I15: 0 | J15: 232.8 | K15: 76.6 | L15: 1950
D16: Wm. Wrigley Jr. Company | E16: 5389.1 | F16: 0.179 | G16: 632 | H16: 964.6489 | I16: 1000 | J16: 1578.5 | K16: 1189.1 | L16: 16400
D17: General Mills, Inc. | E17: 11640 | F17: 0.208 | G17: 1144 | H17: 2421.12 | I17: 3599.1 | J17: 3843.9 | K17: 6223.1 | L17: 28500
D18: Mars, Incorporated | E18: 25000 | F18: n/a | G18: n/a | H18: n/a | I18: n/a | J18: n/a | K18: n/a | L18: 48000
E20: Market Cap | F20: Shares | G20: Stock Price | H20: PE Ratio | I20: Bond Rating | J20: Beta | K20: Dividend Yield | L20: Tax Rate
D21: Cadbury plc | E21: 26046.15 | F21: 2109000000 | G21: 12.35 | H21: 16.621666 | I21: Aa | J21: 0.95 | K21: 0.021 | L21: 0.3
D22: Kraft Foods Inc. | E22: 46230.336 | F22: 1547200000 | G22: 29.88 | H22: 16.221171 | I22: Aaa | J22: 0.75 | K22: 0.036 | L22: 0.355
D23: Lance, Inc. | E23: 594.44416 | F23: 31204418 | G23: 19.05 | H23: 23.777767 | I23: n/a | J23: 0.9 | K23: 0.034 | L23: 0.37
D24: The Hershey Company | E24: 8144.2712 | F24: 227049657 | G24: 35.87 | H24: 16.967232 | I24: Aa | J24: 0.7 | K24: 0.033 | L24: 0.36
D25: Tootsie Roll Industries, Inc. | E25: 1368.0342 | F25: 54941131 | G25: 24.9 | H25: 24.873348 | I25: n/a | J25: 0.85 | K25: 0.013 | L25: 0.33
D26: Wm. Wrigley Jr. Company | E26: 15899.302 | F26: 275742319 | G26: 57.66 | H26: 25.157124 | I26: A | J26: 0.7 | K26: 0.022 | L26: 0.32
D27: General Mills, Inc. | E27: 17760.96 | F27: 336000000 | G27: 52.86 | H27: 15.525315 | I27: A | J27: 0.65 | K27: 0.031 | L27: 0.343
D29: Data sources: Value Line Investment Survey, February 1, 2008, and case writer estimates.
D31: Company Info
D33: Cadbury plc was in the global confectionery business. It offered chocolate, mints, gum, and other candy under a variety of brand names (Cadbury Crème Egg, Dentyne, Éclairs, Green & Blacks, Halls, the Natural Confectionery Company, and Trident, to name a few). Based in Uxbridge, the United Kingdom, Cadbury was founded in 1783.
D34: Kraft Foods Inc. manufactured and marketed packaged-food and grocery products worldwide. The company made snacks, including cookies, crackers, and chocolate confectionary; beverages; cheese; and other grocery products. It also offered convenient meals, packaged dinners, lunch combinations, and processed meats. Kraft marketed its products under various brand names, including Nabisco cookies and crackers; Kraft cheeses; Oscar Mayer meats; Philadelphia cream cheese; Maxwell House coffee; its Oreo cookie brand; Milka chocolates; and LU biscuits.
D35: Lance, Inc., based in North California, engaged in the manufacture, marketing, and distribution of various snack food products. It offered sandwich crackers and cookies, potato chips, crackers, cookies, other salty snacks, restaurant-style crackers, and candy. The company also provided private-brand products to grocery- and mass merchandisers and discount stores using store brands or Lance brands.
D36: The Hershey Company engaged in the manufacturing, marketing, selling, and distributing of various chocolate and confectionery products, food and beverage enhancers, and gums and mints. Its chocolate and confectionery products included chocolate bars and cocoa mixes, handcrafted chocolate gifts, and natural and organic chocolate products. The company’s snack foods included snack mix, cookies, granola bars, and a variety of cookies.
D37: Tootsie Roll Industries, Inc., produced candy, caramel, and sugar-based confectionery under various trademarks, including Tootsie Roll, Tootsie Roll Pops, Charms, Blow-Pop, Blue Razz, Junior Mint, Charleston Chew, Sugar Daddy, Sugar Babies, Andes, Cry Baby, and Nik-L-Nip.
D38: General Mills, Inc., engaged globally in the manufacture and marketing of branded consumer foods. The company also supplied branded and unbranded food products to the food service and commercial-baking industries. Its product line was composed of cereals, yogurt, soup, dry dinners, shelf-stable and frozen vegetables, refrigerated and frozen dough products, dessert and baking mixes, frozen pizza, grains, fruit and savory snacks, and ice cream and other frozen desserts, as well as various organic products, including granola bars and cereal.
D40: Source: Yahoo! Finance, December 2009, and company Web sites.
D42: Comparable Analysis & Relevant Ratios
C44: Relevant Ratios | E44: Enterprise Value | F44: PE | G44: Revenue | H44: EBIT | I44: Employees
D45: Cadbury plc | E45: =E21+I11 -> 28429.15 | F45: =H21 -> 16.621666 | G45: =E45/E11 -> 1.7930716 | H45: =E45/H11 -> 13.615493 | I45: =E45/L11 -> 0.77973533
D46: Kraft Foods Inc. | E46: =E22+I12 -> 56830.336 | F46: =H22 -> 16.221171 | G46: =E46/E12 -> 1.535955 | H46: =E46/H12 -> 9.3088183 | I46: =E46/L12 -> 0.63144818
D47: Lance, Inc. | E47: =E23+I13 -> 644.44416 | F47: =H23 -> 23.777767 | G47: =E47/E13 -> 0.84241067 | H47: =E47/H13 -> 9.3601186 | I47: =E47/L13 -> 0.1342592
D48: The Hershey Company | E48: =E24+I14 -> 9424.2712 | F48: =H24 -> 16.967232 | G48: =E48/E14 -> 1.9050477 | H48: =E48/H14 -> 7.9376989 | I48: =E48/L14 -> 0.73627119
D49: Tootsie Roll Industries, Inc. | E49: =E25+I15 -> 1368.0342 | F49: =H25 -> 24.873348 | G49: =E49/E15 -> 2.7749172 | H49: =E49/H15 -> 13.874586 | I49: =E49/L15 -> 0.70155598
D50: General Mills, Inc. | E50: =E27+I17 -> 21360.06 | F50: =H27 -> 15.525315 | G50: =E50/E17 -> 1.8350567 | H50: =E50/H17 -> 8.822388 | I50: =E50/L17 -> 0.74947579
C52: Industry Average | E52: =AVERAGE(E45:E50) -> 19676.049 | F52: =AVERAGE(F45:F50) -> 18.99775 | G52: =AVERAGE(G45:G50) -> 1.7810765 | H52: =AVERAGE(H45:H50) -> 10.486517 | I52: =AVERAGE(I45:I50) -> 0.62212428
...

Sheet Exhibit 9
A1: Exhibit 9
A2: WM. WRIGLEY JR. COMPANY
A3: Wrigley Selected Financial Data
A4: (all numbers, except per share numbers, in millions of dollars)
A6: Operating Data | B6: 2003 | C6: 2004 | D6: 2005 | E6: 2006 | F6: 2007
A7: Revenues | B7: 3069.088 | C7: 3648.592 | D7: 4159.306 | E7: 4686.011 | F7: 5389.1
A8: Gross profit | B8: 1792.353 | C8: 2038.614 | D8: 2255.904 | E8: 2429.822 | F8: 2840.782
A9: Income taxes | B9: 205.647 | C9: 227.542 | D9: 237.408 | E9: 239.67 | F9: 300.158
A10: Net earnings | B10: 445.894 | C10: 492.954 | D10: 517.252 | E10: 529.377 | F10: 632.005
A11: Per share of common stock (diluted) | B11: 1.5856602 | C11: 1.74905 | D11: 1.8323816 | E11: 1.9015047 | F11: 2.2782097
A12: Dividends paid
A13: Per share of common stock | B13: 0.692 | C13: 0.74 | D13: 0.86 | E13: 0.992 | F13: 1.126
A14: As a percentage of net earnings | B14: 0.43641127 | C14: 0.42151811 | D14: 0.46713989 | E14: 0.52011242 | F14: 0.4905847
A15: Average shares outstanding | B15: 281204 | C15: 280796 | D15: 280964 | E15: 277556 | F15: 275357
A17: Other Financial Data | B17: 2003 | C17: 2004 | D17: 2005 | E17: 2006 | F17: 2007
A18: Net property, plant and equipment | B18: 956.18 | C18: 1142.62 | D18: 1282.412 | E18: 1422.516 | F18: 1560.064
A19: Total assets | B19: 2520.41 | C19: 3166.703 | D19: 4460.201 | E19: 4661.598 | F19: 5231.512
A20: Working capital | B20: 825.797 | C20: 787.94 | D20: 325.283 | E20: 454.098 | F20: 448.658
A21: Debt | B21: 0 | C21: 90 | D21: 1100 | E21: 1065 | F21: 1000
A22: Stockholders’ equity | B22: 1820.821 | C22: 2178.684 | D22: 2214.422 | E22: 2388.092 | F22: 2817.48
A23: Return on average equity | B23: 0.24488624 | C23: 0.22626228 | D23: 0.2335833 | E23: 0.22167362 | F23: 0.2243157
A24: Stockholders of record at close of year | B24: 40379 | C24: 40779 | D24: 40545 | E24: 40986 | F24: 41020
A25: Employees at close of year | B25: 12000 | C25: 14800 | D25: 14300 | E25: 15800 | F25: 16400
A26: Sales per employee | B26: 0.25575733 | C26: 0.24652649 | D26: 0.29086056 | E26: 0.29658297 | F26: 0.32860366
A28: Data sources: Wm. Wrigley Jr. Company annual report, 2007, and case writer estimates.

Sheet Exhibit 12
B1: Exhibit 12
B2: WM. WRIGLEY JR. COMPANY
B3: Bonds Market Interest Rates, April 2008
C5: Corporate bonds
C7: Aaa | D7: 0.0555
C8: Aa | D8: 0.0593
C9: A | D9: 0.063
C10: Baa | D10: 0.0697
C12: Data source: Mergent Bond Record, April 2008.
C15: Treasury bills
C17: 1-month | D17: 0.0107
C18: 3-month | D18: 0.0131
C19: 6-month | D19: 0.0158
C20: 1-year | D20: 0.0174
C21: 2-year | D21: 0.0205
C22: 3-year | D22: 0.0223
C23: 5-year | D23: 0.0284
C24: 7-year | D24: 0.0319
C25: 10-year | D25: 0.0368
C26: 20-year | D26: 0.044
C27: 30-year | D27: 0.0444
C29: Data source: U.S. Treasury.
C32: Market Risk Premium | E32: 0.06
C34: Source: Case writer estimates.
